{
  "nbformat": 4,
  "nbformat_minor": 0,
  "metadata": {
    "colab": {
      "provenance": [],
      "gpuType": "T4",
      "include_colab_link": true
    },
    "kernelspec": {
      "name": "python3",
      "display_name": "Python 3"
    },
    "language_info": {
      "name": "python"
    },
    "accelerator": "GPU"
  },
  "cells": [
    {
      "cell_type": "markdown",
      "metadata": {
        "id": "view-in-github",
        "colab_type": "text"
      },
      "source": [
        "<a href=\"https://colab.research.google.com/github/iko-ai/ibibio-tts/blob/master/train.ipynb\" target=\"_parent\"><img src=\"https://colab.research.google.com/assets/colab-badge.svg\" alt=\"Open In Colab\"/></a>"
      ]
    },
    {
      "cell_type": "code",
      "execution_count": 2,
      "metadata": {
        "colab": {
          "base_uri": "https://localhost:8080/"
        },
        "id": "519BayIw16w9",
        "outputId": "72b0dc33-8183-4e91-cef0-ba6c51849219"
      },
      "outputs": [
        {
          "output_type": "stream",
          "name": "stdout",
          "text": [
            "Mounted at /content/drive\n"
          ]
        }
      ],
      "source": [
        "from google.colab import drive\n",
        "drive.mount('/content/drive')"
      ]
    },
    {
      "cell_type": "code",
      "source": [
        "import os\n",
        "from glob import glob\n",
        "import csv\n",
        "import random\n",
        "import pandas as pd"
      ],
      "metadata": {
        "id": "CV6hrveq2eyI"
      },
      "execution_count": 16,
      "outputs": []
    },
    {
      "cell_type": "code",
      "source": [
        "print(len(os.listdir(\"/content/drive/MyDrive/dataset/wav\")))"
      ],
      "metadata": {
        "colab": {
          "base_uri": "https://localhost:8080/"
        },
        "id": "diC0lprL5UcB",
        "outputId": "f118c244-fed9-4763-baa8-506ec808bd57"
      },
      "execution_count": 4,
      "outputs": [
        {
          "output_type": "stream",
          "name": "stdout",
          "text": [
            "604\n"
          ]
        }
      ]
    },
    {
      "cell_type": "code",
      "source": [
        "# Paths\n",
        "input_excel_path = '/content/metadata.xlsx'\n",
        "output_csv_path = '/content/drive/MyDrive/dataset/metadata.csv'\n",
        "\n",
        "# Read the Excel file\n",
        "df = pd.read_excel(input_excel_path, engine='openpyxl')\n",
        "\n",
        "# Save the dataframe as a CSV file\n",
        "df.to_csv(output_csv_path, index=False, encoding='utf-8')\n",
        "\n",
        "print(\"Excel file has been successfully converted to CSV.\")\n"
      ],
      "metadata": {
        "colab": {
          "base_uri": "https://localhost:8080/"
        },
        "id": "M4Xl15zB4vSr",
        "outputId": "e67949ef-48a7-4ac7-e828-1d5e301d5c1d"
      },
      "execution_count": null,
      "outputs": [
        {
          "output_type": "stream",
          "name": "stdout",
          "text": [
            "Excel file has been successfully converted to CSV.\n"
          ]
        }
      ]
    },
    {
      "cell_type": "code",
      "source": [
        "# Paths\n",
        "input_csv_path = '/content/drive/MyDrive/dataset/metadata.csv'\n",
        "input_wavs_dir = '/content/drive/MyDrive/dataset/wav'\n",
        "output_dir = '/content/drive/MyDrive/dataset/wav_split'\n",
        "train_txt_path = os.path.join(output_dir, 'train.txt')\n",
        "val_txt_path = os.path.join(output_dir, 'val.txt')"
      ],
      "metadata": {
        "id": "a5kFSaG65nPW"
      },
      "execution_count": null,
      "outputs": []
    },
    {
      "cell_type": "code",
      "source": [
        "# Create the output directory if it doesn't exist\n",
        "os.makedirs(output_dir, exist_ok=True)\n",
        "\n",
        "# Read the input CSV\n",
        "with open(input_csv_path, 'r') as csv_file:\n",
        "    reader = csv.DictReader(csv_file)\n",
        "    data = list(reader)\n",
        "\n",
        "# Shuffle the data\n",
        "random.shuffle(data)\n",
        "\n",
        "# Split the data into 80% training and 20% validation\n",
        "split_index = int(0.8 * len(data))\n",
        "train_data = data[:split_index]\n",
        "val_data = data[split_index:]\n",
        "\n",
        "# Function to write data to a text file\n",
        "def write_data(file_path, data):\n",
        "    with open(file_path, 'w') as file:\n",
        "        for row in data:\n",
        "            filename = row['Filepath']\n",
        "            transcription = row['Transcription']\n",
        "            file.write(f\"wavs/{filename}|{transcription}\\n\")\n"
      ],
      "metadata": {
        "id": "SrqJKEJs2NA9"
      },
      "execution_count": null,
      "outputs": []
    },
    {
      "cell_type": "code",
      "source": [
        "# Write the training and validation data to their respective files\n",
        "write_data(train_txt_path, train_data)\n",
        "write_data(val_txt_path, val_data)\n",
        "\n",
        "print(\"Dataset has been successfully split and saved.\")"
      ],
      "metadata": {
        "colab": {
          "base_uri": "https://localhost:8080/"
        },
        "id": "AvpNLDAn5rSy",
        "outputId": "28366018-2073-423b-ddff-2f9528177627"
      },
      "execution_count": null,
      "outputs": [
        {
          "output_type": "stream",
          "name": "stdout",
          "text": [
            "Dataset has been successfully split and saved.\n"
          ]
        }
      ]
    },
    {
      "cell_type": "code",
      "source": [
        "!git clone https://github.com/iko-ai/ibibio-tts.git"
      ],
      "metadata": {
        "colab": {
          "base_uri": "https://localhost:8080/"
        },
        "id": "FuIFNM9D5tC5",
        "outputId": "59515aa0-822b-42c2-834f-a1b028e96ef2"
      },
      "execution_count": 9,
      "outputs": [
        {
          "output_type": "stream",
          "name": "stdout",
          "text": [
            "Cloning into 'ibibio-tts'...\n",
            "remote: Enumerating objects: 16659, done.\u001b[K\n",
            "remote: Counting objects: 100% (428/428), done.\u001b[K\n",
            "remote: Compressing objects: 100% (219/219), done.\u001b[K\n",
            "remote: Total 16659 (delta 236), reused 365 (delta 208), pack-reused 16231\u001b[K\n",
            "Receiving objects: 100% (16659/16659), 12.16 MiB | 6.28 MiB/s, done.\n",
            "Resolving deltas: 100% (13349/13349), done.\n"
          ]
        }
      ]
    },
    {
      "cell_type": "code",
      "source": [
        "#%cd ../"
      ],
      "metadata": {
        "id": "Euf_Uq4yJ7C-"
      },
      "execution_count": 10,
      "outputs": []
    },
    {
      "cell_type": "code",
      "source": [
        "#%cd ibibio-texttospeech/codes\n",
        "#%cd codes\n",
        "%cd /content/ibibio-tts/codes"
      ],
      "metadata": {
        "colab": {
          "base_uri": "https://localhost:8080/"
        },
        "id": "rg4QnjEu6Ngz",
        "outputId": "6aba05e1-df85-4813-d485-7b3f74dbbf1d"
      },
      "execution_count": 11,
      "outputs": [
        {
          "output_type": "stream",
          "name": "stdout",
          "text": [
            "/content/ibibio-tts/codes\n"
          ]
        }
      ]
    },
    {
      "cell_type": "code",
      "source": [
        "!pip install -r requirements.laxed.txt"
      ],
      "metadata": {
        "id": "QwsDLpEm6Swl"
      },
      "execution_count": null,
      "outputs": []
    },
    {
      "cell_type": "code",
      "source": [],
      "metadata": {
        "id": "gpmugun9LkEd"
      },
      "execution_count": 12,
      "outputs": []
    },
    {
      "cell_type": "code",
      "source": [
        "!wget https://huggingface.co/Gatozu35/tortoise-tts/resolve/main/dvae.pth -O /content/ibibio-tts/experiments/dvae.pth\n",
        "!wget https://huggingface.co/jbetker/tortoise-tts-v2/resolve/main/.models/autoregressive.pth -O /content/ibibio-tts/experiments/autoregressive.pth"
      ],
      "metadata": {
        "id": "qixhVDpCPilC",
        "colab": {
          "base_uri": "https://localhost:8080/"
        },
        "outputId": "6c97e1c7-86c6-4151-fe04-a9a138c18e57"
      },
      "execution_count": 13,
      "outputs": [
        {
          "output_type": "stream",
          "name": "stdout",
          "text": [
            "--2024-05-30 08:04:30--  https://huggingface.co/Gatozu35/tortoise-tts/resolve/main/dvae.pth\n",
            "Resolving huggingface.co (huggingface.co)... 13.33.30.114, 13.33.30.49, 13.33.30.23, ...\n",
            "Connecting to huggingface.co (huggingface.co)|13.33.30.114|:443... connected.\n",
            "HTTP request sent, awaiting response... 302 Found\n",
            "Location: https://cdn-lfs.huggingface.co/repos/9f/83/9f8300e5ccd418d283e72c07d1851f269dbd2ca7bae49cee21285965d9bebe14/a990825371506c16bcf0e8167bf24ccf82f65bb6a1dbcbfcf058d76f9b197e35?response-content-disposition=attachment%3B+filename*%3DUTF-8%27%27dvae.pth%3B+filename%3D%22dvae.pth%22%3B&Expires=1717315470&Policy=eyJTdGF0ZW1lbnQiOlt7IkNvbmRpdGlvbiI6eyJEYXRlTGVzc1RoYW4iOnsiQVdTOkVwb2NoVGltZSI6MTcxNzMxNTQ3MH19LCJSZXNvdXJjZSI6Imh0dHBzOi8vY2RuLWxmcy5odWdnaW5nZmFjZS5jby9yZXBvcy85Zi84My85ZjgzMDBlNWNjZDQxOGQyODNlNzJjMDdkMTg1MWYyNjlkYmQyY2E3YmFlNDljZWUyMTI4NTk2NWQ5YmViZTE0L2E5OTA4MjUzNzE1MDZjMTZiY2YwZTgxNjdiZjI0Y2NmODJmNjViYjZhMWRiY2JmY2YwNThkNzZmOWIxOTdlMzU%7EcmVzcG9uc2UtY29udGVudC1kaXNwb3NpdGlvbj0qIn1dfQ__&Signature=sGhlEq7aseMin52J-2lmL0CWs7DZAeWdJBLGd1eavnvCCzNu6aLF5pbR7GBIFKRlcDRzFkyMg9cPdvn%7E30l8tldDaxUNylKnPWmqob93ZpyGfQtYc5J3t%7EI27wFu2aDqnSxXUDkv6OIPxiCumt2nA%7E6AO1WXwmf3szOhSJxpb9hkkiQnWs1bVuAZiNtkjaKbrrLPO56yVo2fhcPttiUBVtLHKnDVvY6a2WVQeeDY3nWEIf%7E7AtyQMVDEWjh7HbzWM8oF87pdvCBupbsnXulyIeNV7k0oVbCuI3mXvBlE-v1cG1YDmBdtzSpr7k-b%7Ey3xQKAJwVTq4BbA6mod-6-2pg__&Key-Pair-Id=KVTP0A1DKRTAX [following]\n",
            "--2024-05-30 08:04:31--  https://cdn-lfs.huggingface.co/repos/9f/83/9f8300e5ccd418d283e72c07d1851f269dbd2ca7bae49cee21285965d9bebe14/a990825371506c16bcf0e8167bf24ccf82f65bb6a1dbcbfcf058d76f9b197e35?response-content-disposition=attachment%3B+filename*%3DUTF-8%27%27dvae.pth%3B+filename%3D%22dvae.pth%22%3B&Expires=1717315470&Policy=eyJTdGF0ZW1lbnQiOlt7IkNvbmRpdGlvbiI6eyJEYXRlTGVzc1RoYW4iOnsiQVdTOkVwb2NoVGltZSI6MTcxNzMxNTQ3MH19LCJSZXNvdXJjZSI6Imh0dHBzOi8vY2RuLWxmcy5odWdnaW5nZmFjZS5jby9yZXBvcy85Zi84My85ZjgzMDBlNWNjZDQxOGQyODNlNzJjMDdkMTg1MWYyNjlkYmQyY2E3YmFlNDljZWUyMTI4NTk2NWQ5YmViZTE0L2E5OTA4MjUzNzE1MDZjMTZiY2YwZTgxNjdiZjI0Y2NmODJmNjViYjZhMWRiY2JmY2YwNThkNzZmOWIxOTdlMzU%7EcmVzcG9uc2UtY29udGVudC1kaXNwb3NpdGlvbj0qIn1dfQ__&Signature=sGhlEq7aseMin52J-2lmL0CWs7DZAeWdJBLGd1eavnvCCzNu6aLF5pbR7GBIFKRlcDRzFkyMg9cPdvn%7E30l8tldDaxUNylKnPWmqob93ZpyGfQtYc5J3t%7EI27wFu2aDqnSxXUDkv6OIPxiCumt2nA%7E6AO1WXwmf3szOhSJxpb9hkkiQnWs1bVuAZiNtkjaKbrrLPO56yVo2fhcPttiUBVtLHKnDVvY6a2WVQeeDY3nWEIf%7E7AtyQMVDEWjh7HbzWM8oF87pdvCBupbsnXulyIeNV7k0oVbCuI3mXvBlE-v1cG1YDmBdtzSpr7k-b%7Ey3xQKAJwVTq4BbA6mod-6-2pg__&Key-Pair-Id=KVTP0A1DKRTAX\n",
            "Resolving cdn-lfs.huggingface.co (cdn-lfs.huggingface.co)... 108.156.133.109, 108.156.133.51, 108.156.133.103, ...\n",
            "Connecting to cdn-lfs.huggingface.co (cdn-lfs.huggingface.co)|108.156.133.109|:443... connected.\n",
            "HTTP request sent, awaiting response... 200 OK\n",
            "Length: 239873286 (229M) [binary/octet-stream]\n",
            "Saving to: ‘/content/ibibio-tts/experiments/dvae.pth’\n",
            "\n",
            "/content/ibibio-tts 100%[===================>] 228.76M   252MB/s    in 0.9s    \n",
            "\n",
            "2024-05-30 08:04:31 (252 MB/s) - ‘/content/ibibio-tts/experiments/dvae.pth’ saved [239873286/239873286]\n",
            "\n",
            "--2024-05-30 08:04:32--  https://huggingface.co/jbetker/tortoise-tts-v2/resolve/main/.models/autoregressive.pth\n",
            "Resolving huggingface.co (huggingface.co)... 13.33.30.23, 13.33.30.49, 13.33.30.114, ...\n",
            "Connecting to huggingface.co (huggingface.co)|13.33.30.23|:443... connected.\n",
            "HTTP request sent, awaiting response... 302 Found\n",
            "Location: https://cdn-lfs.huggingface.co/repos/57/08/5708d35b6a2408439b3511ccdaa992754f65f8e182278ecb9f654fc46a46f9fb/9c6651b9996df6cef6a1fc459738ae207ab60f902ec49b4d0623ca8ab6110d51?response-content-disposition=attachment%3B+filename*%3DUTF-8%27%27autoregressive.pth%3B+filename%3D%22autoregressive.pth%22%3B&Expires=1717315472&Policy=eyJTdGF0ZW1lbnQiOlt7IkNvbmRpdGlvbiI6eyJEYXRlTGVzc1RoYW4iOnsiQVdTOkVwb2NoVGltZSI6MTcxNzMxNTQ3Mn19LCJSZXNvdXJjZSI6Imh0dHBzOi8vY2RuLWxmcy5odWdnaW5nZmFjZS5jby9yZXBvcy81Ny8wOC81NzA4ZDM1YjZhMjQwODQzOWIzNTExY2NkYWE5OTI3NTRmNjVmOGUxODIyNzhlY2I5ZjY1NGZjNDZhNDZmOWZiLzljNjY1MWI5OTk2ZGY2Y2VmNmExZmM0NTk3MzhhZTIwN2FiNjBmOTAyZWM0OWI0ZDA2MjNjYThhYjYxMTBkNTE%7EcmVzcG9uc2UtY29udGVudC1kaXNwb3NpdGlvbj0qIn1dfQ__&Signature=rPvtWidG7lNQXmcZrYdhek%7E9LA%7EkmU9hbbClolrehtrRKjRfoXxulUTGxsZ5P5lQYb2R6OvQnB4DldKNban8hFciZYEdHg6vdPpxRwOOSpWurXsh-GTh9xMHLPGTvV1LVqMg3B6fQyAisSas4Q409%7EWzrvMOg6voxbpTTJmkUPrvldc4rjD-qenWnZxdpky-i4RwwMSRyPaGiVWbvp4dwxsdtV34HklWXfrPP2Pye8cKEif0fyWHtq3nggiZHRzk7xqBIqlJASPvUf2fHO3qZijAQIjp0fLzdA1EjeQZysMfGYTY1yV8Adcw9wxLwTplsTIxQ5aZQfkFch-H%7EIxZQA__&Key-Pair-Id=KVTP0A1DKRTAX [following]\n",
            "--2024-05-30 08:04:32--  https://cdn-lfs.huggingface.co/repos/57/08/5708d35b6a2408439b3511ccdaa992754f65f8e182278ecb9f654fc46a46f9fb/9c6651b9996df6cef6a1fc459738ae207ab60f902ec49b4d0623ca8ab6110d51?response-content-disposition=attachment%3B+filename*%3DUTF-8%27%27autoregressive.pth%3B+filename%3D%22autoregressive.pth%22%3B&Expires=1717315472&Policy=eyJTdGF0ZW1lbnQiOlt7IkNvbmRpdGlvbiI6eyJEYXRlTGVzc1RoYW4iOnsiQVdTOkVwb2NoVGltZSI6MTcxNzMxNTQ3Mn19LCJSZXNvdXJjZSI6Imh0dHBzOi8vY2RuLWxmcy5odWdnaW5nZmFjZS5jby9yZXBvcy81Ny8wOC81NzA4ZDM1YjZhMjQwODQzOWIzNTExY2NkYWE5OTI3NTRmNjVmOGUxODIyNzhlY2I5ZjY1NGZjNDZhNDZmOWZiLzljNjY1MWI5OTk2ZGY2Y2VmNmExZmM0NTk3MzhhZTIwN2FiNjBmOTAyZWM0OWI0ZDA2MjNjYThhYjYxMTBkNTE%7EcmVzcG9uc2UtY29udGVudC1kaXNwb3NpdGlvbj0qIn1dfQ__&Signature=rPvtWidG7lNQXmcZrYdhek%7E9LA%7EkmU9hbbClolrehtrRKjRfoXxulUTGxsZ5P5lQYb2R6OvQnB4DldKNban8hFciZYEdHg6vdPpxRwOOSpWurXsh-GTh9xMHLPGTvV1LVqMg3B6fQyAisSas4Q409%7EWzrvMOg6voxbpTTJmkUPrvldc4rjD-qenWnZxdpky-i4RwwMSRyPaGiVWbvp4dwxsdtV34HklWXfrPP2Pye8cKEif0fyWHtq3nggiZHRzk7xqBIqlJASPvUf2fHO3qZijAQIjp0fLzdA1EjeQZysMfGYTY1yV8Adcw9wxLwTplsTIxQ5aZQfkFch-H%7EIxZQA__&Key-Pair-Id=KVTP0A1DKRTAX\n",
            "Resolving cdn-lfs.huggingface.co (cdn-lfs.huggingface.co)... 108.156.133.109, 108.156.133.51, 108.156.133.103, ...\n",
            "Connecting to cdn-lfs.huggingface.co (cdn-lfs.huggingface.co)|108.156.133.109|:443... connected.\n",
            "HTTP request sent, awaiting response... 200 OK\n",
            "Length: 1716988501 (1.6G) [application/zip]\n",
            "Saving to: ‘/content/ibibio-tts/experiments/autoregressive.pth’\n",
            "\n",
            "/content/ibibio-tts 100%[===================>]   1.60G   255MB/s    in 14s     \n",
            "\n",
            "2024-05-30 08:04:46 (116 MB/s) - ‘/content/ibibio-tts/experiments/autoregressive.pth’ saved [1716988501/1716988501]\n",
            "\n"
          ]
        }
      ]
    },
    {
      "cell_type": "markdown",
      "source": [
        "# Make sure the waveform audio has a sampling rate of 22.05kHz\n",
        "Install librosa using the following command (automatically installs soundfile as well):\n",
        "pip install librosa"
      ],
      "metadata": {
        "id": "ui5jUdh7ST4K"
      }
    },
    {
      "cell_type": "code",
      "source": [
        "import librosa\n",
        "import soundfile as sf\n",
        "\n",
        "def resample_wav_file(input_file, target_sampling_rate=22050):\n",
        "    # Load audio file\n",
        "    audio, sampling_rate = librosa.load(input_file, sr=None)\n",
        "\n",
        "    # Check if the sampling rate matches the target\n",
        "    if sampling_rate != target_sampling_rate:\n",
        "\n",
        "        # Resample audio to the target sampling rate\n",
        "        audio_resampled = librosa.resample(audio, orig_sr=sampling_rate, target_sr=target_sampling_rate)\n",
        "\n",
        "        # Overwrite the input file with the resampled audio\n",
        "        sf.write(input_file, audio_resampled, target_sampling_rate)"
      ],
      "metadata": {
        "id": "ja7Stce2QfY6"
      },
      "execution_count": 14,
      "outputs": []
    },
    {
      "cell_type": "code",
      "source": [
        "# Resample all audio samples to 22.05kHz\n",
        "dataset_path = '/content/drive/MyDrive/dataset/wav'\n",
        "for wav_file in glob(dataset_path + \"*.wav\"):\n",
        "    resample_wav_file(input_file)"
      ],
      "metadata": {
        "id": "m5XZqSloQf9o"
      },
      "execution_count": 17,
      "outputs": []
    },
    {
      "cell_type": "markdown",
      "source": [
        "# Fine-Tune THE AUTOREGRESSIVE MODEL"
      ],
      "metadata": {
        "id": "CpAZSlxqTRUz"
      }
    },
    {
      "cell_type": "code",
      "source": [
        "!python3 /content/ibibio-tts/codes/train.py -opt /content/ibibio-tts/experiments/custom_language_gpt.yml"
      ],
      "metadata": {
        "colab": {
          "base_uri": "https://localhost:8080/"
        },
        "id": "tQtEm55VQgLK",
        "outputId": "7f01f1f6-b5c9-4551-90d4-60f6ddadba39"
      },
      "execution_count": 23,
      "outputs": [
        {
          "output_type": "stream",
          "name": "stdout",
          "text": [
            "Disabled distributed training.\n",
            "Path already exists. Rename it to [/content/ibibio-tts/experiments/custom_language_gpt_archived_240530-081303]\n",
            "24-05-30 08:13:03.350 - INFO:   name: custom_language_gpt\n",
            "  model: extensibletrainer\n",
            "  scale: 1\n",
            "  gpu_ids: [0]\n",
            "  start_step: 0\n",
            "  checkpointing_enabled: True\n",
            "  fp16: False\n",
            "  use_8bit: True\n",
            "  wandb: False\n",
            "  use_tb_logger: True\n",
            "  datasets:[\n",
            "    train:[\n",
            "      name: train_dataset\n",
            "      n_workers: 8\n",
            "      batch_size: 128\n",
            "      mode: paired_voice_audio\n",
            "      path: /content/drive/MyDrive/dataset/wav_split/train.txt\n",
            "      fetcher_mode: ['lj']\n",
            "      phase: train\n",
            "      max_wav_length: 255995\n",
            "      max_text_length: 200\n",
            "      sample_rate: 22050\n",
            "      load_conditioning: True\n",
            "      num_conditioning_candidates: 2\n",
            "      conditioning_length: 44000\n",
            "      use_bpe_tokenizer: True\n",
            "      load_aligned_codes: False\n",
            "      tokenizer_vocab: /content/custom_language_tokenizer.json\n",
            "      data_type: img\n",
            "    ]\n",
            "    val:[\n",
            "      name: val_dataset\n",
            "      n_workers: 1\n",
            "      batch_size: 64\n",
            "      mode: paired_voice_audio\n",
            "      path: /content/drive/MyDrive/dataset/wav_split/val.txt\n",
            "      fetcher_mode: ['lj']\n",
            "      phase: val\n",
            "      max_wav_length: 255995\n",
            "      max_text_length: 200\n",
            "      sample_rate: 22050\n",
            "      load_conditioning: True\n",
            "      num_conditioning_candidates: 2\n",
            "      conditioning_length: 44000\n",
            "      use_bpe_tokenizer: True\n",
            "      load_aligned_codes: False\n",
            "      tokenizer_vocab: /content/custom_language_tokenizer.json\n",
            "      data_type: img\n",
            "    ]\n",
            "  ]\n",
            "  steps:[\n",
            "    gpt_train:[\n",
            "      training: gpt\n",
            "      loss_log_buffer: 500\n",
            "      optimizer: adamw\n",
            "      optimizer_params:[\n",
            "        lr: 1e-05\n",
            "        triton: False\n",
            "        weight_decay: 0.01\n",
            "        beta1: 0.9\n",
            "        beta2: 0.96\n",
            "      ]\n",
            "      clip_grad_eps: 4\n",
            "      injectors:[\n",
            "        paired_to_mel:[\n",
            "          type: torch_mel_spectrogram\n",
            "          mel_norm_file: /content/ibibio-tts/experiments/clips_mel_norms.pth\n",
            "          in: wav\n",
            "          out: paired_mel\n",
            "        ]\n",
            "        paired_cond_to_mel:[\n",
            "          type: for_each\n",
            "          subtype: torch_mel_spectrogram\n",
            "          mel_norm_file: /content/ibibio-tts/experiments/clips_mel_norms.pth\n",
            "          in: conditioning\n",
            "          out: paired_conditioning_mel\n",
            "        ]\n",
            "        to_codes:[\n",
            "          type: discrete_token\n",
            "          in: paired_mel\n",
            "          out: paired_mel_codes\n",
            "          dvae_config: /content/ibibio-tts/experiments/train_diffusion_vocoder_22k_level.yml\n",
            "        ]\n",
            "        paired_fwd_text:[\n",
            "          type: generator\n",
            "          generator: gpt\n",
            "          in: ['paired_conditioning_mel', 'padded_text', 'text_lengths', 'paired_mel_codes', 'wav_lengths']\n",
            "          out: ['loss_text_ce', 'loss_mel_ce', 'logits']\n",
            "        ]\n",
            "      ]\n",
            "      losses:[\n",
            "        text_ce:[\n",
            "          type: direct\n",
            "          weight: 0.01\n",
            "          key: loss_text_ce\n",
            "        ]\n",
            "        mel_ce:[\n",
            "          type: direct\n",
            "          weight: 1\n",
            "          key: loss_mel_ce\n",
            "        ]\n",
            "      ]\n",
            "    ]\n",
            "  ]\n",
            "  networks:[\n",
            "    gpt:[\n",
            "      type: generator\n",
            "      which_model_G: unified_voice2\n",
            "      kwargs:[\n",
            "        layers: 30\n",
            "        model_dim: 1024\n",
            "        heads: 16\n",
            "        max_text_tokens: 402\n",
            "        max_mel_tokens: 604\n",
            "        max_conditioning_inputs: 2\n",
            "        mel_length_compression: 1024\n",
            "        number_text_tokens: 256\n",
            "        number_mel_codes: 8194\n",
            "        start_mel_token: 8192\n",
            "        stop_mel_token: 8193\n",
            "        start_text_token: 255\n",
            "        train_solo_embeddings: False\n",
            "        use_mel_codes_as_input: True\n",
            "        checkpointing: True\n",
            "        tortoise_compat: True\n",
            "      ]\n",
            "    ]\n",
            "  ]\n",
            "  path:[\n",
            "    pretrain_model_gpt: /content/ibibio-tts/experiments/autoregressive.pth\n",
            "    strict_load: True\n",
            "    root: /content/ibibio-tts\n",
            "    experiments_root: /content/ibibio-tts/experiments/custom_language_gpt\n",
            "    models: /content/ibibio-tts/experiments/custom_language_gpt/models\n",
            "    training_state: /content/ibibio-tts/experiments/custom_language_gpt/training_state\n",
            "    log: /content/ibibio-tts/experiments/custom_language_gpt\n",
            "    val_images: /content/ibibio-tts/experiments/custom_language_gpt/val_images\n",
            "  ]\n",
            "  train:[\n",
            "    niter: 500\n",
            "    warmup_iter: -1\n",
            "    mega_batch_factor: 4\n",
            "    val_freq: 500\n",
            "    default_lr_scheme: MultiStepLR\n",
            "    gen_lr_steps: [500, 1000, 1400, 1800]\n",
            "    lr_gamma: 0.5\n",
            "    ema_enabled: False\n",
            "  ]\n",
            "  eval:[\n",
            "    pure: True\n",
            "  ]\n",
            "  logger:[\n",
            "    print_freq: 100\n",
            "    save_checkpoint_freq: 500\n",
            "    visuals: ['gen', 'mel']\n",
            "    visual_debug_rate: 500\n",
            "    is_mel_spectrogram: True\n",
            "    disable_state_saving: True\n",
            "  ]\n",
            "  upgrades:[\n",
            "    number_of_checkpoints_to_save: 0\n",
            "    number_of_states_to_save: 0\n",
            "  ]\n",
            "  is_train: True\n",
            "  dist: False\n",
            "\n",
            "2024-05-30 08:13:03.719467: E external/local_xla/xla/stream_executor/cuda/cuda_dnn.cc:9261] Unable to register cuDNN factory: Attempting to register factory for plugin cuDNN when one has already been registered\n",
            "2024-05-30 08:13:03.719526: E external/local_xla/xla/stream_executor/cuda/cuda_fft.cc:607] Unable to register cuFFT factory: Attempting to register factory for plugin cuFFT when one has already been registered\n",
            "2024-05-30 08:13:03.721012: E external/local_xla/xla/stream_executor/cuda/cuda_blas.cc:1515] Unable to register cuBLAS factory: Attempting to register factory for plugin cuBLAS when one has already been registered\n",
            "2024-05-30 08:13:05.075533: W tensorflow/compiler/tf2tensorrt/utils/py_utils.cc:38] TF-TRT Warning: Could not find TensorRT\n",
            "24-05-30 08:13:06.535 - INFO: Random seed: 3897\n",
            "/usr/local/lib/python3.10/dist-packages/torch/utils/data/dataloader.py:558: UserWarning: This DataLoader will create 8 worker processes in total. Our suggested max number of worker in current system is 2, which is smaller than what this DataLoader is going to create. Please be aware that excessive worker creation might get DataLoader running slow or even freeze, lower the worker number to avoid potential slowness/freeze if necessary.\n",
            "  warnings.warn(_create_warning_msg(\n",
            "24-05-30 08:13:08.450 - INFO: Number of training data elements: 482, iters: 4\n",
            "24-05-30 08:13:08.450 - INFO: Total epochs needed: 125 for iters 500\n",
            "24-05-30 08:13:08.455 - INFO: Number of val images in [val_dataset]: 121\n",
            "/usr/local/lib/python3.10/dist-packages/transformers/configuration_utils.py:380: UserWarning: Passing `gradient_checkpointing` to a config initialization is deprecated and will be removed in v5 Transformers. Using `model.gradient_checkpointing_enable()` instead, or if you are using the `Trainer` API, pass `gradient_checkpointing=True` in your `TrainingArguments`.\n",
            "  warnings.warn(\n",
            "Loading from ../experiments/dvae.pth\n",
            "24-05-30 08:13:19.073 - INFO: Network gpt structure: DataParallel, with parameters: 421,526,786\n",
            "24-05-30 08:13:19.074 - INFO: UnifiedVoice(\n",
            "  (conditioning_encoder): ConditioningEncoder(\n",
            "    (init): Conv1d(80, 1024, kernel_size=(1,), stride=(1,))\n",
            "    (attn): Sequential(\n",
            "      (0): AttentionBlock(\n",
            "        (norm): GroupNorm32(32, 1024, eps=1e-05, affine=True)\n",
            "        (qkv): Conv1d(1024, 3072, kernel_size=(1,), stride=(1,))\n",
            "        (attention): QKVAttentionLegacy()\n",
            "        (x_proj): Identity()\n",
            "        (proj_out): Conv1d(1024, 1024, kernel_size=(1,), stride=(1,))\n",
            "      )\n",
            "      (1): AttentionBlock(\n",
            "        (norm): GroupNorm32(32, 1024, eps=1e-05, affine=True)\n",
            "        (qkv): Conv1d(1024, 3072, kernel_size=(1,), stride=(1,))\n",
            "        (attention): QKVAttentionLegacy()\n",
            "        (x_proj): Identity()\n",
            "        (proj_out): Conv1d(1024, 1024, kernel_size=(1,), stride=(1,))\n",
            "      )\n",
            "      (2): AttentionBlock(\n",
            "        (norm): GroupNorm32(32, 1024, eps=1e-05, affine=True)\n",
            "        (qkv): Conv1d(1024, 3072, kernel_size=(1,), stride=(1,))\n",
            "        (attention): QKVAttentionLegacy()\n",
            "        (x_proj): Identity()\n",
            "        (proj_out): Conv1d(1024, 1024, kernel_size=(1,), stride=(1,))\n",
            "      )\n",
            "      (3): AttentionBlock(\n",
            "        (norm): GroupNorm32(32, 1024, eps=1e-05, affine=True)\n",
            "        (qkv): Conv1d(1024, 3072, kernel_size=(1,), stride=(1,))\n",
            "        (attention): QKVAttentionLegacy()\n",
            "        (x_proj): Identity()\n",
            "        (proj_out): Conv1d(1024, 1024, kernel_size=(1,), stride=(1,))\n",
            "      )\n",
            "      (4): AttentionBlock(\n",
            "        (norm): GroupNorm32(32, 1024, eps=1e-05, affine=True)\n",
            "        (qkv): Conv1d(1024, 3072, kernel_size=(1,), stride=(1,))\n",
            "        (attention): QKVAttentionLegacy()\n",
            "        (x_proj): Identity()\n",
            "        (proj_out): Conv1d(1024, 1024, kernel_size=(1,), stride=(1,))\n",
            "      )\n",
            "      (5): AttentionBlock(\n",
            "        (norm): GroupNorm32(32, 1024, eps=1e-05, affine=True)\n",
            "        (qkv): Conv1d(1024, 3072, kernel_size=(1,), stride=(1,))\n",
            "        (attention): QKVAttentionLegacy()\n",
            "        (x_proj): Identity()\n",
            "        (proj_out): Conv1d(1024, 1024, kernel_size=(1,), stride=(1,))\n",
            "      )\n",
            "    )\n",
            "  )\n",
            "  (text_embedding): Embedding(256, 1024)\n",
            "  (mel_embedding): Embedding(8194, 1024)\n",
            "  (gpt): GPT2Model(\n",
            "    (drop): Dropout(p=0.1, inplace=False)\n",
            "    (h): ModuleList(\n",
            "      (0-29): 30 x GPT2Block(\n",
            "        (ln_1): LayerNorm((1024,), eps=1e-05, elementwise_affine=True)\n",
            "        (attn): GPT2Attention(\n",
            "          (c_attn): Conv1D()\n",
            "          (c_proj): Conv1D()\n",
            "          (attn_dropout): Dropout(p=0.1, inplace=False)\n",
            "          (resid_dropout): Dropout(p=0.1, inplace=False)\n",
            "        )\n",
            "        (ln_2): LayerNorm((1024,), eps=1e-05, elementwise_affine=True)\n",
            "        (mlp): GPT2MLP(\n",
            "          (c_fc): Conv1D()\n",
            "          (c_proj): Conv1D()\n",
            "          (act): NewGELUActivation()\n",
            "          (dropout): Dropout(p=0.1, inplace=False)\n",
            "        )\n",
            "      )\n",
            "    )\n",
            "    (ln_f): LayerNorm((1024,), eps=1e-05, elementwise_affine=True)\n",
            "  )\n",
            "  (mel_pos_embedding): LearnedPositionEmbeddings(\n",
            "    (emb): Embedding(608, 1024)\n",
            "  )\n",
            "  (text_pos_embedding): LearnedPositionEmbeddings(\n",
            "    (emb): Embedding(404, 1024)\n",
            "  )\n",
            "  (final_norm): LayerNorm((1024,), eps=1e-05, elementwise_affine=True)\n",
            "  (text_head): Linear(in_features=1024, out_features=256, bias=True)\n",
            "  (mel_head): Linear(in_features=1024, out_features=8194, bias=True)\n",
            ")\n",
            "24-05-30 08:13:19.074 - INFO: Loading model for [/content/ibibio-tts/experiments/autoregressive.pth]\n",
            "24-05-30 08:13:21.084 - INFO: Start training from epoch: 0, iter: 0\n",
            "  0% 0/3 [00:00<?, ?it/s]/usr/local/lib/python3.10/dist-packages/torch/utils/data/dataloader.py:558: UserWarning: This DataLoader will create 8 worker processes in total. Our suggested max number of worker in current system is 2, which is smaller than what this DataLoader is going to create. Please be aware that excessive worker creation might get DataLoader running slow or even freeze, lower the worker number to avoid potential slowness/freeze if necessary.\n",
            "  warnings.warn(_create_warning_msg(\n",
            "/usr/lib/python3.10/multiprocessing/popen_fork.py:66: RuntimeWarning: os.fork() was called. os.fork() is incompatible with multithreaded code, and JAX is multithreaded, so this will likely lead to a deadlock.\n",
            "  self.pid = os.fork()\n",
            "  0% 0/3 [00:00<?, ?it/s]\n",
            "Traceback (most recent call last):\n",
            "  File \"/content/ibibio-tts/codes/train.py\", line 399, in <module>\n",
            "    trainer.do_training()\n",
            "  File \"/content/ibibio-tts/codes/train.py\", line 353, in do_training\n",
            "    for train_data in tq_ldr:\n",
            "  File \"/usr/local/lib/python3.10/dist-packages/tqdm/std.py\", line 1181, in __iter__\n",
            "    for obj in iterable:\n",
            "  File \"/usr/local/lib/python3.10/dist-packages/torch/utils/data/dataloader.py\", line 631, in __next__\n",
            "    data = self._next_data()\n",
            "  File \"/usr/local/lib/python3.10/dist-packages/torch/utils/data/dataloader.py\", line 1346, in _next_data\n",
            "    return self._process_data(data)\n",
            "  File \"/usr/local/lib/python3.10/dist-packages/torch/utils/data/dataloader.py\", line 1372, in _process_data\n",
            "    data.reraise()\n",
            "  File \"/usr/local/lib/python3.10/dist-packages/torch/_utils.py\", line 705, in reraise\n",
            "    raise exception\n",
            "FileNotFoundError: Caught FileNotFoundError in DataLoader worker process 0.\n",
            "Original Traceback (most recent call last):\n",
            "  File \"/content/ibibio-tts/codes/data/audio/paired_voice_audio_dataset.py\", line 194, in __getitem__\n",
            "    tseq, wav, text, path, type = self.get_wav_text_pair(self.audiopaths_and_text[index])\n",
            "  File \"/content/ibibio-tts/codes/data/audio/paired_voice_audio_dataset.py\", line 178, in get_wav_text_pair\n",
            "    wav = load_audio(audiopath, self.sample_rate)\n",
            "  File \"/content/ibibio-tts/codes/data/audio/unsupervised_audio_dataset.py\", line 19, in load_audio\n",
            "    audio, lsr = load_wav_to_torch(audiopath)\n",
            "  File \"/content/ibibio-tts/codes/models/audio/tts/tacotron2/taco_utils.py\", line 17, in load_wav_to_torch\n",
            "    sampling_rate, data = read(full_path)\n",
            "  File \"/usr/local/lib/python3.10/dist-packages/scipy/io/wavfile.py\", line 647, in read\n",
            "    fid = open(filename, 'rb')\n",
            "FileNotFoundError: [Errno 2] No such file or directory: '/content/drive/MyDrive/dataset/wav_split/wavs//content/drive/MyDrive/dataset/wav/304.wav'\n",
            "\n",
            "During handling of the above exception, another exception occurred:\n",
            "\n",
            "Traceback (most recent call last):\n",
            "  File \"/content/ibibio-tts/codes/data/audio/paired_voice_audio_dataset.py\", line 194, in __getitem__\n",
            "    tseq, wav, text, path, type = self.get_wav_text_pair(self.audiopaths_and_text[index])\n",
            "  File \"/content/ibibio-tts/codes/data/audio/paired_voice_audio_dataset.py\", line 178, in get_wav_text_pair\n",
            "    wav = load_audio(audiopath, self.sample_rate)\n",
            "  File \"/content/ibibio-tts/codes/data/audio/unsupervised_audio_dataset.py\", line 19, in load_audio\n",
            "    audio, lsr = load_wav_to_torch(audiopath)\n",
            "  File \"/content/ibibio-tts/codes/models/audio/tts/tacotron2/taco_utils.py\", line 17, in load_wav_to_torch\n",
            "    sampling_rate, data = read(full_path)\n",
            "  File \"/usr/local/lib/python3.10/dist-packages/scipy/io/wavfile.py\", line 647, in read\n",
            "    fid = open(filename, 'rb')\n",
            "FileNotFoundError: [Errno 2] No such file or directory: '/content/drive/MyDrive/dataset/wav_split/wavs//content/drive/MyDrive/dataset/wav/289.wav'\n",
            "\n",
            "During handling of the above exception, another exception occurred:\n",
            "\n",
            "Traceback (most recent call last):\n",
            "  File \"/content/ibibio-tts/codes/data/audio/paired_voice_audio_dataset.py\", line 194, in __getitem__\n",
            "    tseq, wav, text, path, type = self.get_wav_text_pair(self.audiopaths_and_text[index])\n",
            "  File \"/content/ibibio-tts/codes/data/audio/paired_voice_audio_dataset.py\", line 178, in get_wav_text_pair\n",
            "    wav = load_audio(audiopath, self.sample_rate)\n",
            "  File \"/content/ibibio-tts/codes/data/audio/unsupervised_audio_dataset.py\", line 19, in load_audio\n",
            "    audio, lsr = load_wav_to_torch(audiopath)\n",
            "  File \"/content/ibibio-tts/codes/models/audio/tts/tacotron2/taco_utils.py\", line 17, in load_wav_to_torch\n",
            "    sampling_rate, data = read(full_path)\n",
            "  File \"/usr/local/lib/python3.10/dist-packages/scipy/io/wavfile.py\", line 647, in read\n",
            "    fid = open(filename, 'rb')\n",
            "FileNotFoundError: [Errno 2] No such file or directory: '/content/drive/MyDrive/dataset/wav_split/wavs//content/drive/MyDrive/dataset/wav/488.wav'\n",
            "\n",
            "During handling of the above exception, another exception occurred:\n",
            "\n",
            "Traceback (most recent call last):\n",
            "  File \"/content/ibibio-tts/codes/data/audio/paired_voice_audio_dataset.py\", line 194, in __getitem__\n",
            "    tseq, wav, text, path, type = self.get_wav_text_pair(self.audiopaths_and_text[index])\n",
            "  File \"/content/ibibio-tts/codes/data/audio/paired_voice_audio_dataset.py\", line 178, in get_wav_text_pair\n",
            "    wav = load_audio(audiopath, self.sample_rate)\n",
            "  File \"/content/ibibio-tts/codes/data/audio/unsupervised_audio_dataset.py\", line 19, in load_audio\n",
            "    audio, lsr = load_wav_to_torch(audiopath)\n",
            "  File \"/content/ibibio-tts/codes/models/audio/tts/tacotron2/taco_utils.py\", line 17, in load_wav_to_torch\n",
            "    sampling_rate, data = read(full_path)\n",
            "  File \"/usr/local/lib/python3.10/dist-packages/scipy/io/wavfile.py\", line 647, in read\n",
            "    fid = open(filename, 'rb')\n",
            "FileNotFoundError: [Errno 2] No such file or directory: '/content/drive/MyDrive/dataset/wav_split/wavs//content/drive/MyDrive/dataset/wav/263.wav'\n",
            "\n",
            "During handling of the above exception, another exception occurred:\n",
            "\n",
            "Traceback (most recent call last):\n",
            "  File \"/content/ibibio-tts/codes/data/audio/paired_voice_audio_dataset.py\", line 194, in __getitem__\n",
            "    tseq, wav, text, path, type = self.get_wav_text_pair(self.audiopaths_and_text[index])\n",
            "  File \"/content/ibibio-tts/codes/data/audio/paired_voice_audio_dataset.py\", line 178, in get_wav_text_pair\n",
            "    wav = load_audio(audiopath, self.sample_rate)\n",
            "  File \"/content/ibibio-tts/codes/data/audio/unsupervised_audio_dataset.py\", line 19, in load_audio\n",
            "    audio, lsr = load_wav_to_torch(audiopath)\n",
            "  File \"/content/ibibio-tts/codes/models/audio/tts/tacotron2/taco_utils.py\", line 17, in load_wav_to_torch\n",
            "    sampling_rate, data = read(full_path)\n",
            "  File \"/usr/local/lib/python3.10/dist-packages/scipy/io/wavfile.py\", line 647, in read\n",
            "    fid = open(filename, 'rb')\n",
            "FileNotFoundError: [Errno 2] No such file or directory: '/content/drive/MyDrive/dataset/wav_split/wavs//content/drive/MyDrive/dataset/wav/374.wav'\n",
            "\n",
            "During handling of the above exception, another exception occurred:\n",
            "\n",
            "Traceback (most recent call last):\n",
            "  File \"/content/ibibio-tts/codes/data/audio/paired_voice_audio_dataset.py\", line 194, in __getitem__\n",
            "    tseq, wav, text, path, type = self.get_wav_text_pair(self.audiopaths_and_text[index])\n",
            "  File \"/content/ibibio-tts/codes/data/audio/paired_voice_audio_dataset.py\", line 178, in get_wav_text_pair\n",
            "    wav = load_audio(audiopath, self.sample_rate)\n",
            "  File \"/content/ibibio-tts/codes/data/audio/unsupervised_audio_dataset.py\", line 19, in load_audio\n",
            "    audio, lsr = load_wav_to_torch(audiopath)\n",
            "  File \"/content/ibibio-tts/codes/models/audio/tts/tacotron2/taco_utils.py\", line 17, in load_wav_to_torch\n",
            "    sampling_rate, data = read(full_path)\n",
            "  File \"/usr/local/lib/python3.10/dist-packages/scipy/io/wavfile.py\", line 647, in read\n",
            "    fid = open(filename, 'rb')\n",
            "FileNotFoundError: [Errno 2] No such file or directory: '/content/drive/MyDrive/dataset/wav_split/wavs//content/drive/MyDrive/dataset/wav/486.wav'\n",
            "\n",
            "During handling of the above exception, another exception occurred:\n",
            "\n",
            "Traceback (most recent call last):\n",
            "  File \"/content/ibibio-tts/codes/data/audio/paired_voice_audio_dataset.py\", line 194, in __getitem__\n",
            "    tseq, wav, text, path, type = self.get_wav_text_pair(self.audiopaths_and_text[index])\n",
            "  File \"/content/ibibio-tts/codes/data/audio/paired_voice_audio_dataset.py\", line 178, in get_wav_text_pair\n",
            "    wav = load_audio(audiopath, self.sample_rate)\n",
            "  File \"/content/ibibio-tts/codes/data/audio/unsupervised_audio_dataset.py\", line 19, in load_audio\n",
            "    audio, lsr = load_wav_to_torch(audiopath)\n",
            "  File \"/content/ibibio-tts/codes/models/audio/tts/tacotron2/taco_utils.py\", line 17, in load_wav_to_torch\n",
            "    sampling_rate, data = read(full_path)\n",
            "  File \"/usr/local/lib/python3.10/dist-packages/scipy/io/wavfile.py\", line 647, in read\n",
            "    fid = open(filename, 'rb')\n",
            "FileNotFoundError: [Errno 2] No such file or directory: '/content/drive/MyDrive/dataset/wav_split/wavs//content/drive/MyDrive/dataset/wav/27.wav'\n",
            "\n",
            "During handling of the above exception, another exception occurred:\n",
            "\n",
            "Traceback (most recent call last):\n",
            "  File \"/content/ibibio-tts/codes/data/audio/paired_voice_audio_dataset.py\", line 194, in __getitem__\n",
            "    tseq, wav, text, path, type = self.get_wav_text_pair(self.audiopaths_and_text[index])\n",
            "  File \"/content/ibibio-tts/codes/data/audio/paired_voice_audio_dataset.py\", line 178, in get_wav_text_pair\n",
            "    wav = load_audio(audiopath, self.sample_rate)\n",
            "  File \"/content/ibibio-tts/codes/data/audio/unsupervised_audio_dataset.py\", line 19, in load_audio\n",
            "    audio, lsr = load_wav_to_torch(audiopath)\n",
            "  File \"/content/ibibio-tts/codes/models/audio/tts/tacotron2/taco_utils.py\", line 17, in load_wav_to_torch\n",
            "    sampling_rate, data = read(full_path)\n",
            "  File \"/usr/local/lib/python3.10/dist-packages/scipy/io/wavfile.py\", line 647, in read\n",
            "    fid = open(filename, 'rb')\n",
            "FileNotFoundError: [Errno 2] No such file or directory: '/content/drive/MyDrive/dataset/wav_split/wavs//content/drive/MyDrive/dataset/wav/628.wav'\n",
            "\n",
            "During handling of the above exception, another exception occurred:\n",
            "\n",
            "Traceback (most recent call last):\n",
            "  File \"/content/ibibio-tts/codes/data/audio/paired_voice_audio_dataset.py\", line 194, in __getitem__\n",
            "    tseq, wav, text, path, type = self.get_wav_text_pair(self.audiopaths_and_text[index])\n",
            "  File \"/content/ibibio-tts/codes/data/audio/paired_voice_audio_dataset.py\", line 177, in get_wav_text_pair\n",
            "    text_seq = self.get_text(text)\n",
            "  File \"/content/ibibio-tts/codes/data/audio/paired_voice_audio_dataset.py\", line 186, in get_text\n",
            "    assert not torch.any(tokens == 1)\n",
            "AssertionError\n",
            "\n",
            "During handling of the above exception, another exception occurred:\n",
            "\n",
            "Traceback (most recent call last):\n",
            "  File \"/content/ibibio-tts/codes/data/audio/paired_voice_audio_dataset.py\", line 194, in __getitem__\n",
            "    tseq, wav, text, path, type = self.get_wav_text_pair(self.audiopaths_and_text[index])\n",
            "  File \"/content/ibibio-tts/codes/data/audio/paired_voice_audio_dataset.py\", line 178, in get_wav_text_pair\n",
            "    wav = load_audio(audiopath, self.sample_rate)\n",
            "  File \"/content/ibibio-tts/codes/data/audio/unsupervised_audio_dataset.py\", line 19, in load_audio\n",
            "    audio, lsr = load_wav_to_torch(audiopath)\n",
            "  File \"/content/ibibio-tts/codes/models/audio/tts/tacotron2/taco_utils.py\", line 17, in load_wav_to_torch\n",
            "    sampling_rate, data = read(full_path)\n",
            "  File \"/usr/local/lib/python3.10/dist-packages/scipy/io/wavfile.py\", line 647, in read\n",
            "    fid = open(filename, 'rb')\n",
            "FileNotFoundError: [Errno 2] No such file or directory: '/content/drive/MyDrive/dataset/wav_split/wavs//content/drive/MyDrive/dataset/wav/57.wav'\n",
            "\n",
            "During handling of the above exception, another exception occurred:\n",
            "\n",
            "Traceback (most recent call last):\n",
            "  File \"/content/ibibio-tts/codes/data/audio/paired_voice_audio_dataset.py\", line 194, in __getitem__\n",
            "    tseq, wav, text, path, type = self.get_wav_text_pair(self.audiopaths_and_text[index])\n",
            "  File \"/content/ibibio-tts/codes/data/audio/paired_voice_audio_dataset.py\", line 178, in get_wav_text_pair\n",
            "    wav = load_audio(audiopath, self.sample_rate)\n",
            "  File \"/content/ibibio-tts/codes/data/audio/unsupervised_audio_dataset.py\", line 19, in load_audio\n",
            "    audio, lsr = load_wav_to_torch(audiopath)\n",
            "  File \"/content/ibibio-tts/codes/models/audio/tts/tacotron2/taco_utils.py\", line 17, in load_wav_to_torch\n",
            "    sampling_rate, data = read(full_path)\n",
            "  File \"/usr/local/lib/python3.10/dist-packages/scipy/io/wavfile.py\", line 647, in read\n",
            "    fid = open(filename, 'rb')\n",
            "FileNotFoundError: [Errno 2] No such file or directory: '/content/drive/MyDrive/dataset/wav_split/wavs//content/drive/MyDrive/dataset/wav/77.wav'\n",
            "\n",
            "During handling of the above exception, another exception occurred:\n",
            "\n",
            "Traceback (most recent call last):\n",
            "  File \"/content/ibibio-tts/codes/data/audio/paired_voice_audio_dataset.py\", line 194, in __getitem__\n",
            "    tseq, wav, text, path, type = self.get_wav_text_pair(self.audiopaths_and_text[index])\n",
            "  File \"/content/ibibio-tts/codes/data/audio/paired_voice_audio_dataset.py\", line 178, in get_wav_text_pair\n",
            "    wav = load_audio(audiopath, self.sample_rate)\n",
            "  File \"/content/ibibio-tts/codes/data/audio/unsupervised_audio_dataset.py\", line 19, in load_audio\n",
            "    audio, lsr = load_wav_to_torch(audiopath)\n",
            "  File \"/content/ibibio-tts/codes/models/audio/tts/tacotron2/taco_utils.py\", line 17, in load_wav_to_torch\n",
            "    sampling_rate, data = read(full_path)\n",
            "  File \"/usr/local/lib/python3.10/dist-packages/scipy/io/wavfile.py\", line 647, in read\n",
            "    fid = open(filename, 'rb')\n",
            "FileNotFoundError: [Errno 2] No such file or directory: '/content/drive/MyDrive/dataset/wav_split/wavs//content/drive/MyDrive/dataset/wav/191.wav'\n",
            "\n",
            "During handling of the above exception, another exception occurred:\n",
            "\n",
            "Traceback (most recent call last):\n",
            "  File \"/content/ibibio-tts/codes/data/audio/paired_voice_audio_dataset.py\", line 194, in __getitem__\n",
            "    tseq, wav, text, path, type = self.get_wav_text_pair(self.audiopaths_and_text[index])\n",
            "  File \"/content/ibibio-tts/codes/data/audio/paired_voice_audio_dataset.py\", line 178, in get_wav_text_pair\n",
            "    wav = load_audio(audiopath, self.sample_rate)\n",
            "  File \"/content/ibibio-tts/codes/data/audio/unsupervised_audio_dataset.py\", line 19, in load_audio\n",
            "    audio, lsr = load_wav_to_torch(audiopath)\n",
            "  File \"/content/ibibio-tts/codes/models/audio/tts/tacotron2/taco_utils.py\", line 17, in load_wav_to_torch\n",
            "    sampling_rate, data = read(full_path)\n",
            "  File \"/usr/local/lib/python3.10/dist-packages/scipy/io/wavfile.py\", line 647, in read\n",
            "    fid = open(filename, 'rb')\n",
            "FileNotFoundError: [Errno 2] No such file or directory: '/content/drive/MyDrive/dataset/wav_split/wavs//content/drive/MyDrive/dataset/wav/631.wav'\n",
            "\n",
            "During handling of the above exception, another exception occurred:\n",
            "\n",
            "Traceback (most recent call last):\n",
            "  File \"/content/ibibio-tts/codes/data/audio/paired_voice_audio_dataset.py\", line 194, in __getitem__\n",
            "    tseq, wav, text, path, type = self.get_wav_text_pair(self.audiopaths_and_text[index])\n",
            "  File \"/content/ibibio-tts/codes/data/audio/paired_voice_audio_dataset.py\", line 177, in get_wav_text_pair\n",
            "    text_seq = self.get_text(text)\n",
            "  File \"/content/ibibio-tts/codes/data/audio/paired_voice_audio_dataset.py\", line 186, in get_text\n",
            "    assert not torch.any(tokens == 1)\n",
            "AssertionError\n",
            "\n",
            "During handling of the above exception, another exception occurred:\n",
            "\n",
            "Traceback (most recent call last):\n",
            "  File \"/content/ibibio-tts/codes/data/audio/paired_voice_audio_dataset.py\", line 194, in __getitem__\n",
            "    tseq, wav, text, path, type = self.get_wav_text_pair(self.audiopaths_and_text[index])\n",
            "  File \"/content/ibibio-tts/codes/data/audio/paired_voice_audio_dataset.py\", line 178, in get_wav_text_pair\n",
            "    wav = load_audio(audiopath, self.sample_rate)\n",
            "  File \"/content/ibibio-tts/codes/data/audio/unsupervised_audio_dataset.py\", line 19, in load_audio\n",
            "    audio, lsr = load_wav_to_torch(audiopath)\n",
            "  File \"/content/ibibio-tts/codes/models/audio/tts/tacotron2/taco_utils.py\", line 17, in load_wav_to_torch\n",
            "    sampling_rate, data = read(full_path)\n",
            "  File \"/usr/local/lib/python3.10/dist-packages/scipy/io/wavfile.py\", line 647, in read\n",
            "    fid = open(filename, 'rb')\n",
            "FileNotFoundError: [Errno 2] No such file or directory: '/content/drive/MyDrive/dataset/wav_split/wavs//content/drive/MyDrive/dataset/wav/50.wav'\n",
            "\n",
            "During handling of the above exception, another exception occurred:\n",
            "\n",
            "Traceback (most recent call last):\n",
            "  File \"/content/ibibio-tts/codes/data/audio/paired_voice_audio_dataset.py\", line 194, in __getitem__\n",
            "    tseq, wav, text, path, type = self.get_wav_text_pair(self.audiopaths_and_text[index])\n",
            "  File \"/content/ibibio-tts/codes/data/audio/paired_voice_audio_dataset.py\", line 178, in get_wav_text_pair\n",
            "    wav = load_audio(audiopath, self.sample_rate)\n",
            "  File \"/content/ibibio-tts/codes/data/audio/unsupervised_audio_dataset.py\", line 19, in load_audio\n",
            "    audio, lsr = load_wav_to_torch(audiopath)\n",
            "  File \"/content/ibibio-tts/codes/models/audio/tts/tacotron2/taco_utils.py\", line 17, in load_wav_to_torch\n",
            "    sampling_rate, data = read(full_path)\n",
            "  File \"/usr/local/lib/python3.10/dist-packages/scipy/io/wavfile.py\", line 647, in read\n",
            "    fid = open(filename, 'rb')\n",
            "FileNotFoundError: [Errno 2] No such file or directory: '/content/drive/MyDrive/dataset/wav_split/wavs//content/drive/MyDrive/dataset/wav/160.wav'\n",
            "\n",
            "During handling of the above exception, another exception occurred:\n",
            "\n",
            "Traceback (most recent call last):\n",
            "  File \"/content/ibibio-tts/codes/data/audio/paired_voice_audio_dataset.py\", line 194, in __getitem__\n",
            "    tseq, wav, text, path, type = self.get_wav_text_pair(self.audiopaths_and_text[index])\n",
            "  File \"/content/ibibio-tts/codes/data/audio/paired_voice_audio_dataset.py\", line 178, in get_wav_text_pair\n",
            "    wav = load_audio(audiopath, self.sample_rate)\n",
            "  File \"/content/ibibio-tts/codes/data/audio/unsupervised_audio_dataset.py\", line 19, in load_audio\n",
            "    audio, lsr = load_wav_to_torch(audiopath)\n",
            "  File \"/content/ibibio-tts/codes/models/audio/tts/tacotron2/taco_utils.py\", line 17, in load_wav_to_torch\n",
            "    sampling_rate, data = read(full_path)\n",
            "  File \"/usr/local/lib/python3.10/dist-packages/scipy/io/wavfile.py\", line 647, in read\n",
            "    fid = open(filename, 'rb')\n",
            "FileNotFoundError: [Errno 2] No such file or directory: '/content/drive/MyDrive/dataset/wav_split/wavs//content/drive/MyDrive/dataset/wav/332.wav'\n",
            "\n",
            "During handling of the above exception, another exception occurred:\n",
            "\n",
            "Traceback (most recent call last):\n",
            "  File \"/content/ibibio-tts/codes/data/audio/paired_voice_audio_dataset.py\", line 194, in __getitem__\n",
            "    tseq, wav, text, path, type = self.get_wav_text_pair(self.audiopaths_and_text[index])\n",
            "  File \"/content/ibibio-tts/codes/data/audio/paired_voice_audio_dataset.py\", line 178, in get_wav_text_pair\n",
            "    wav = load_audio(audiopath, self.sample_rate)\n",
            "  File \"/content/ibibio-tts/codes/data/audio/unsupervised_audio_dataset.py\", line 19, in load_audio\n",
            "    audio, lsr = load_wav_to_torch(audiopath)\n",
            "  File \"/content/ibibio-tts/codes/models/audio/tts/tacotron2/taco_utils.py\", line 17, in load_wav_to_torch\n",
            "    sampling_rate, data = read(full_path)\n",
            "  File \"/usr/local/lib/python3.10/dist-packages/scipy/io/wavfile.py\", line 647, in read\n",
            "    fid = open(filename, 'rb')\n",
            "FileNotFoundError: [Errno 2] No such file or directory: '/content/drive/MyDrive/dataset/wav_split/wavs//content/drive/MyDrive/dataset/wav/235.wav'\n",
            "\n",
            "During handling of the above exception, another exception occurred:\n",
            "\n",
            "Traceback (most recent call last):\n",
            "  File \"/content/ibibio-tts/codes/data/audio/paired_voice_audio_dataset.py\", line 194, in __getitem__\n",
            "    tseq, wav, text, path, type = self.get_wav_text_pair(self.audiopaths_and_text[index])\n",
            "  File \"/content/ibibio-tts/codes/data/audio/paired_voice_audio_dataset.py\", line 178, in get_wav_text_pair\n",
            "    wav = load_audio(audiopath, self.sample_rate)\n",
            "  File \"/content/ibibio-tts/codes/data/audio/unsupervised_audio_dataset.py\", line 19, in load_audio\n",
            "    audio, lsr = load_wav_to_torch(audiopath)\n",
            "  File \"/content/ibibio-tts/codes/models/audio/tts/tacotron2/taco_utils.py\", line 17, in load_wav_to_torch\n",
            "    sampling_rate, data = read(full_path)\n",
            "  File \"/usr/local/lib/python3.10/dist-packages/scipy/io/wavfile.py\", line 647, in read\n",
            "    fid = open(filename, 'rb')\n",
            "FileNotFoundError: [Errno 2] No such file or directory: '/content/drive/MyDrive/dataset/wav_split/wavs//content/drive/MyDrive/dataset/wav/421.wav'\n",
            "\n",
            "During handling of the above exception, another exception occurred:\n",
            "\n",
            "Traceback (most recent call last):\n",
            "  File \"/content/ibibio-tts/codes/data/audio/paired_voice_audio_dataset.py\", line 194, in __getitem__\n",
            "    tseq, wav, text, path, type = self.get_wav_text_pair(self.audiopaths_and_text[index])\n",
            "  File \"/content/ibibio-tts/codes/data/audio/paired_voice_audio_dataset.py\", line 178, in get_wav_text_pair\n",
            "    wav = load_audio(audiopath, self.sample_rate)\n",
            "  File \"/content/ibibio-tts/codes/data/audio/unsupervised_audio_dataset.py\", line 19, in load_audio\n",
            "    audio, lsr = load_wav_to_torch(audiopath)\n",
            "  File \"/content/ibibio-tts/codes/models/audio/tts/tacotron2/taco_utils.py\", line 17, in load_wav_to_torch\n",
            "    sampling_rate, data = read(full_path)\n",
            "  File \"/usr/local/lib/python3.10/dist-packages/scipy/io/wavfile.py\", line 647, in read\n",
            "    fid = open(filename, 'rb')\n",
            "FileNotFoundError: [Errno 2] No such file or directory: '/content/drive/MyDrive/dataset/wav_split/wavs//content/drive/MyDrive/dataset/wav/220.wav'\n",
            "\n",
            "During handling of the above exception, another exception occurred:\n",
            "\n",
            "Traceback (most recent call last):\n",
            "  File \"/content/ibibio-tts/codes/data/audio/paired_voice_audio_dataset.py\", line 194, in __getitem__\n",
            "    tseq, wav, text, path, type = self.get_wav_text_pair(self.audiopaths_and_text[index])\n",
            "  File \"/content/ibibio-tts/codes/data/audio/paired_voice_audio_dataset.py\", line 178, in get_wav_text_pair\n",
            "    wav = load_audio(audiopath, self.sample_rate)\n",
            "  File \"/content/ibibio-tts/codes/data/audio/unsupervised_audio_dataset.py\", line 19, in load_audio\n",
            "    audio, lsr = load_wav_to_torch(audiopath)\n",
            "  File \"/content/ibibio-tts/codes/models/audio/tts/tacotron2/taco_utils.py\", line 17, in load_wav_to_torch\n",
            "    sampling_rate, data = read(full_path)\n",
            "  File \"/usr/local/lib/python3.10/dist-packages/scipy/io/wavfile.py\", line 647, in read\n",
            "    fid = open(filename, 'rb')\n",
            "FileNotFoundError: [Errno 2] No such file or directory: '/content/drive/MyDrive/dataset/wav_split/wavs//content/drive/MyDrive/dataset/wav/347.wav'\n",
            "\n",
            "During handling of the above exception, another exception occurred:\n",
            "\n",
            "Traceback (most recent call last):\n",
            "  File \"/content/ibibio-tts/codes/data/audio/paired_voice_audio_dataset.py\", line 194, in __getitem__\n",
            "    tseq, wav, text, path, type = self.get_wav_text_pair(self.audiopaths_and_text[index])\n",
            "  File \"/content/ibibio-tts/codes/data/audio/paired_voice_audio_dataset.py\", line 178, in get_wav_text_pair\n",
            "    wav = load_audio(audiopath, self.sample_rate)\n",
            "  File \"/content/ibibio-tts/codes/data/audio/unsupervised_audio_dataset.py\", line 19, in load_audio\n",
            "    audio, lsr = load_wav_to_torch(audiopath)\n",
            "  File \"/content/ibibio-tts/codes/models/audio/tts/tacotron2/taco_utils.py\", line 17, in load_wav_to_torch\n",
            "    sampling_rate, data = read(full_path)\n",
            "  File \"/usr/local/lib/python3.10/dist-packages/scipy/io/wavfile.py\", line 647, in read\n",
            "    fid = open(filename, 'rb')\n",
            "FileNotFoundError: [Errno 2] No such file or directory: '/content/drive/MyDrive/dataset/wav_split/wavs//content/drive/MyDrive/dataset/wav/478.wav'\n",
            "\n",
            "During handling of the above exception, another exception occurred:\n",
            "\n",
            "Traceback (most recent call last):\n",
            "  File \"/content/ibibio-tts/codes/data/audio/paired_voice_audio_dataset.py\", line 194, in __getitem__\n",
            "    tseq, wav, text, path, type = self.get_wav_text_pair(self.audiopaths_and_text[index])\n",
            "  File \"/content/ibibio-tts/codes/data/audio/paired_voice_audio_dataset.py\", line 178, in get_wav_text_pair\n",
            "    wav = load_audio(audiopath, self.sample_rate)\n",
            "  File \"/content/ibibio-tts/codes/data/audio/unsupervised_audio_dataset.py\", line 19, in load_audio\n",
            "    audio, lsr = load_wav_to_torch(audiopath)\n",
            "  File \"/content/ibibio-tts/codes/models/audio/tts/tacotron2/taco_utils.py\", line 17, in load_wav_to_torch\n",
            "    sampling_rate, data = read(full_path)\n",
            "  File \"/usr/local/lib/python3.10/dist-packages/scipy/io/wavfile.py\", line 647, in read\n",
            "    fid = open(filename, 'rb')\n",
            "FileNotFoundError: [Errno 2] No such file or directory: '/content/drive/MyDrive/dataset/wav_split/wavs//content/drive/MyDrive/dataset/wav/492.wav'\n",
            "\n",
            "During handling of the above exception, another exception occurred:\n",
            "\n",
            "Traceback (most recent call last):\n",
            "  File \"/content/ibibio-tts/codes/data/audio/paired_voice_audio_dataset.py\", line 194, in __getitem__\n",
            "    tseq, wav, text, path, type = self.get_wav_text_pair(self.audiopaths_and_text[index])\n",
            "  File \"/content/ibibio-tts/codes/data/audio/paired_voice_audio_dataset.py\", line 178, in get_wav_text_pair\n",
            "    wav = load_audio(audiopath, self.sample_rate)\n",
            "  File \"/content/ibibio-tts/codes/data/audio/unsupervised_audio_dataset.py\", line 19, in load_audio\n",
            "    audio, lsr = load_wav_to_torch(audiopath)\n",
            "  File \"/content/ibibio-tts/codes/models/audio/tts/tacotron2/taco_utils.py\", line 17, in load_wav_to_torch\n",
            "    sampling_rate, data = read(full_path)\n",
            "  File \"/usr/local/lib/python3.10/dist-packages/scipy/io/wavfile.py\", line 647, in read\n",
            "    fid = open(filename, 'rb')\n",
            "FileNotFoundError: [Errno 2] No such file or directory: '/content/drive/MyDrive/dataset/wav_split/wavs//content/drive/MyDrive/dataset/wav/268.wav'\n",
            "\n",
            "During handling of the above exception, another exception occurred:\n",
            "\n",
            "Traceback (most recent call last):\n",
            "  File \"/content/ibibio-tts/codes/data/audio/paired_voice_audio_dataset.py\", line 194, in __getitem__\n",
            "    tseq, wav, text, path, type = self.get_wav_text_pair(self.audiopaths_and_text[index])\n",
            "  File \"/content/ibibio-tts/codes/data/audio/paired_voice_audio_dataset.py\", line 178, in get_wav_text_pair\n",
            "    wav = load_audio(audiopath, self.sample_rate)\n",
            "  File \"/content/ibibio-tts/codes/data/audio/unsupervised_audio_dataset.py\", line 19, in load_audio\n",
            "    audio, lsr = load_wav_to_torch(audiopath)\n",
            "  File \"/content/ibibio-tts/codes/models/audio/tts/tacotron2/taco_utils.py\", line 17, in load_wav_to_torch\n",
            "    sampling_rate, data = read(full_path)\n",
            "  File \"/usr/local/lib/python3.10/dist-packages/scipy/io/wavfile.py\", line 647, in read\n",
            "    fid = open(filename, 'rb')\n",
            "FileNotFoundError: [Errno 2] No such file or directory: '/content/drive/MyDrive/dataset/wav_split/wavs//content/drive/MyDrive/dataset/wav/310.wav'\n",
            "\n",
            "During handling of the above exception, another exception occurred:\n",
            "\n",
            "Traceback (most recent call last):\n",
            "  File \"/content/ibibio-tts/codes/data/audio/paired_voice_audio_dataset.py\", line 194, in __getitem__\n",
            "    tseq, wav, text, path, type = self.get_wav_text_pair(self.audiopaths_and_text[index])\n",
            "  File \"/content/ibibio-tts/codes/data/audio/paired_voice_audio_dataset.py\", line 178, in get_wav_text_pair\n",
            "    wav = load_audio(audiopath, self.sample_rate)\n",
            "  File \"/content/ibibio-tts/codes/data/audio/unsupervised_audio_dataset.py\", line 19, in load_audio\n",
            "    audio, lsr = load_wav_to_torch(audiopath)\n",
            "  File \"/content/ibibio-tts/codes/models/audio/tts/tacotron2/taco_utils.py\", line 17, in load_wav_to_torch\n",
            "    sampling_rate, data = read(full_path)\n",
            "  File \"/usr/local/lib/python3.10/dist-packages/scipy/io/wavfile.py\", line 647, in read\n",
            "    fid = open(filename, 'rb')\n",
            "FileNotFoundError: [Errno 2] No such file or directory: '/content/drive/MyDrive/dataset/wav_split/wavs//content/drive/MyDrive/dataset/wav/456.wav'\n",
            "\n",
            "During handling of the above exception, another exception occurred:\n",
            "\n",
            "Traceback (most recent call last):\n",
            "  File \"/content/ibibio-tts/codes/data/audio/paired_voice_audio_dataset.py\", line 194, in __getitem__\n",
            "    tseq, wav, text, path, type = self.get_wav_text_pair(self.audiopaths_and_text[index])\n",
            "  File \"/content/ibibio-tts/codes/data/audio/paired_voice_audio_dataset.py\", line 178, in get_wav_text_pair\n",
            "    wav = load_audio(audiopath, self.sample_rate)\n",
            "  File \"/content/ibibio-tts/codes/data/audio/unsupervised_audio_dataset.py\", line 19, in load_audio\n",
            "    audio, lsr = load_wav_to_torch(audiopath)\n",
            "  File \"/content/ibibio-tts/codes/models/audio/tts/tacotron2/taco_utils.py\", line 17, in load_wav_to_torch\n",
            "    sampling_rate, data = read(full_path)\n",
            "  File \"/usr/local/lib/python3.10/dist-packages/scipy/io/wavfile.py\", line 647, in read\n",
            "    fid = open(filename, 'rb')\n",
            "FileNotFoundError: [Errno 2] No such file or directory: '/content/drive/MyDrive/dataset/wav_split/wavs//content/drive/MyDrive/dataset/wav/341.wav'\n",
            "\n",
            "During handling of the above exception, another exception occurred:\n",
            "\n",
            "Traceback (most recent call last):\n",
            "  File \"/content/ibibio-tts/codes/data/audio/paired_voice_audio_dataset.py\", line 194, in __getitem__\n",
            "    tseq, wav, text, path, type = self.get_wav_text_pair(self.audiopaths_and_text[index])\n",
            "  File \"/content/ibibio-tts/codes/data/audio/paired_voice_audio_dataset.py\", line 178, in get_wav_text_pair\n",
            "    wav = load_audio(audiopath, self.sample_rate)\n",
            "  File \"/content/ibibio-tts/codes/data/audio/unsupervised_audio_dataset.py\", line 19, in load_audio\n",
            "    audio, lsr = load_wav_to_torch(audiopath)\n",
            "  File \"/content/ibibio-tts/codes/models/audio/tts/tacotron2/taco_utils.py\", line 17, in load_wav_to_torch\n",
            "    sampling_rate, data = read(full_path)\n",
            "  File \"/usr/local/lib/python3.10/dist-packages/scipy/io/wavfile.py\", line 647, in read\n",
            "    fid = open(filename, 'rb')\n",
            "FileNotFoundError: [Errno 2] No such file or directory: '/content/drive/MyDrive/dataset/wav_split/wavs//content/drive/MyDrive/dataset/wav/307.wav'\n",
            "\n",
            "During handling of the above exception, another exception occurred:\n",
            "\n",
            "Traceback (most recent call last):\n",
            "  File \"/content/ibibio-tts/codes/data/audio/paired_voice_audio_dataset.py\", line 194, in __getitem__\n",
            "    tseq, wav, text, path, type = self.get_wav_text_pair(self.audiopaths_and_text[index])\n",
            "  File \"/content/ibibio-tts/codes/data/audio/paired_voice_audio_dataset.py\", line 178, in get_wav_text_pair\n",
            "    wav = load_audio(audiopath, self.sample_rate)\n",
            "  File \"/content/ibibio-tts/codes/data/audio/unsupervised_audio_dataset.py\", line 19, in load_audio\n",
            "    audio, lsr = load_wav_to_torch(audiopath)\n",
            "  File \"/content/ibibio-tts/codes/models/audio/tts/tacotron2/taco_utils.py\", line 17, in load_wav_to_torch\n",
            "    sampling_rate, data = read(full_path)\n",
            "  File \"/usr/local/lib/python3.10/dist-packages/scipy/io/wavfile.py\", line 647, in read\n",
            "    fid = open(filename, 'rb')\n",
            "FileNotFoundError: [Errno 2] No such file or directory: '/content/drive/MyDrive/dataset/wav_split/wavs//content/drive/MyDrive/dataset/wav/467.wav'\n",
            "\n",
            "During handling of the above exception, another exception occurred:\n",
            "\n",
            "Traceback (most recent call last):\n",
            "  File \"/content/ibibio-tts/codes/data/audio/paired_voice_audio_dataset.py\", line 194, in __getitem__\n",
            "    tseq, wav, text, path, type = self.get_wav_text_pair(self.audiopaths_and_text[index])\n",
            "  File \"/content/ibibio-tts/codes/data/audio/paired_voice_audio_dataset.py\", line 178, in get_wav_text_pair\n",
            "    wav = load_audio(audiopath, self.sample_rate)\n",
            "  File \"/content/ibibio-tts/codes/data/audio/unsupervised_audio_dataset.py\", line 19, in load_audio\n",
            "    audio, lsr = load_wav_to_torch(audiopath)\n",
            "  File \"/content/ibibio-tts/codes/models/audio/tts/tacotron2/taco_utils.py\", line 17, in load_wav_to_torch\n",
            "    sampling_rate, data = read(full_path)\n",
            "  File \"/usr/local/lib/python3.10/dist-packages/scipy/io/wavfile.py\", line 647, in read\n",
            "    fid = open(filename, 'rb')\n",
            "FileNotFoundError: [Errno 2] No such file or directory: '/content/drive/MyDrive/dataset/wav_split/wavs//content/drive/MyDrive/dataset/wav/610.wav'\n",
            "\n",
            "During handling of the above exception, another exception occurred:\n",
            "\n",
            "Traceback (most recent call last):\n",
            "  File \"/content/ibibio-tts/codes/data/audio/paired_voice_audio_dataset.py\", line 194, in __getitem__\n",
            "    tseq, wav, text, path, type = self.get_wav_text_pair(self.audiopaths_and_text[index])\n",
            "  File \"/content/ibibio-tts/codes/data/audio/paired_voice_audio_dataset.py\", line 178, in get_wav_text_pair\n",
            "    wav = load_audio(audiopath, self.sample_rate)\n",
            "  File \"/content/ibibio-tts/codes/data/audio/unsupervised_audio_dataset.py\", line 19, in load_audio\n",
            "    audio, lsr = load_wav_to_torch(audiopath)\n",
            "  File \"/content/ibibio-tts/codes/models/audio/tts/tacotron2/taco_utils.py\", line 17, in load_wav_to_torch\n",
            "    sampling_rate, data = read(full_path)\n",
            "  File \"/usr/local/lib/python3.10/dist-packages/scipy/io/wavfile.py\", line 647, in read\n",
            "    fid = open(filename, 'rb')\n",
            "FileNotFoundError: [Errno 2] No such file or directory: '/content/drive/MyDrive/dataset/wav_split/wavs//content/drive/MyDrive/dataset/wav/276.wav'\n",
            "\n",
            "During handling of the above exception, another exception occurred:\n",
            "\n",
            "Traceback (most recent call last):\n",
            "  File \"/content/ibibio-tts/codes/data/audio/paired_voice_audio_dataset.py\", line 194, in __getitem__\n",
            "    tseq, wav, text, path, type = self.get_wav_text_pair(self.audiopaths_and_text[index])\n",
            "  File \"/content/ibibio-tts/codes/data/audio/paired_voice_audio_dataset.py\", line 178, in get_wav_text_pair\n",
            "    wav = load_audio(audiopath, self.sample_rate)\n",
            "  File \"/content/ibibio-tts/codes/data/audio/unsupervised_audio_dataset.py\", line 19, in load_audio\n",
            "    audio, lsr = load_wav_to_torch(audiopath)\n",
            "  File \"/content/ibibio-tts/codes/models/audio/tts/tacotron2/taco_utils.py\", line 17, in load_wav_to_torch\n",
            "    sampling_rate, data = read(full_path)\n",
            "  File \"/usr/local/lib/python3.10/dist-packages/scipy/io/wavfile.py\", line 647, in read\n",
            "    fid = open(filename, 'rb')\n",
            "FileNotFoundError: [Errno 2] No such file or directory: '/content/drive/MyDrive/dataset/wav_split/wavs//content/drive/MyDrive/dataset/wav/440.wav'\n",
            "\n",
            "During handling of the above exception, another exception occurred:\n",
            "\n",
            "Traceback (most recent call last):\n",
            "  File \"/content/ibibio-tts/codes/data/audio/paired_voice_audio_dataset.py\", line 194, in __getitem__\n",
            "    tseq, wav, text, path, type = self.get_wav_text_pair(self.audiopaths_and_text[index])\n",
            "  File \"/content/ibibio-tts/codes/data/audio/paired_voice_audio_dataset.py\", line 177, in get_wav_text_pair\n",
            "    text_seq = self.get_text(text)\n",
            "  File \"/content/ibibio-tts/codes/data/audio/paired_voice_audio_dataset.py\", line 186, in get_text\n",
            "    assert not torch.any(tokens == 1)\n",
            "AssertionError\n",
            "\n",
            "During handling of the above exception, another exception occurred:\n",
            "\n",
            "Traceback (most recent call last):\n",
            "  File \"/content/ibibio-tts/codes/data/audio/paired_voice_audio_dataset.py\", line 194, in __getitem__\n",
            "    tseq, wav, text, path, type = self.get_wav_text_pair(self.audiopaths_and_text[index])\n",
            "  File \"/content/ibibio-tts/codes/data/audio/paired_voice_audio_dataset.py\", line 178, in get_wav_text_pair\n",
            "    wav = load_audio(audiopath, self.sample_rate)\n",
            "  File \"/content/ibibio-tts/codes/data/audio/unsupervised_audio_dataset.py\", line 19, in load_audio\n",
            "    audio, lsr = load_wav_to_torch(audiopath)\n",
            "  File \"/content/ibibio-tts/codes/models/audio/tts/tacotron2/taco_utils.py\", line 17, in load_wav_to_torch\n",
            "    sampling_rate, data = read(full_path)\n",
            "  File \"/usr/local/lib/python3.10/dist-packages/scipy/io/wavfile.py\", line 647, in read\n",
            "    fid = open(filename, 'rb')\n",
            "FileNotFoundError: [Errno 2] No such file or directory: '/content/drive/MyDrive/dataset/wav_split/wavs//content/drive/MyDrive/dataset/wav/337.wav'\n",
            "\n",
            "During handling of the above exception, another exception occurred:\n",
            "\n",
            "Traceback (most recent call last):\n",
            "  File \"/content/ibibio-tts/codes/data/audio/paired_voice_audio_dataset.py\", line 194, in __getitem__\n",
            "    tseq, wav, text, path, type = self.get_wav_text_pair(self.audiopaths_and_text[index])\n",
            "  File \"/content/ibibio-tts/codes/data/audio/paired_voice_audio_dataset.py\", line 177, in get_wav_text_pair\n",
            "    text_seq = self.get_text(text)\n",
            "  File \"/content/ibibio-tts/codes/data/audio/paired_voice_audio_dataset.py\", line 186, in get_text\n",
            "    assert not torch.any(tokens == 1)\n",
            "AssertionError\n",
            "\n",
            "During handling of the above exception, another exception occurred:\n",
            "\n",
            "Traceback (most recent call last):\n",
            "  File \"/content/ibibio-tts/codes/data/audio/paired_voice_audio_dataset.py\", line 194, in __getitem__\n",
            "    tseq, wav, text, path, type = self.get_wav_text_pair(self.audiopaths_and_text[index])\n",
            "  File \"/content/ibibio-tts/codes/data/audio/paired_voice_audio_dataset.py\", line 178, in get_wav_text_pair\n",
            "    wav = load_audio(audiopath, self.sample_rate)\n",
            "  File \"/content/ibibio-tts/codes/data/audio/unsupervised_audio_dataset.py\", line 19, in load_audio\n",
            "    audio, lsr = load_wav_to_torch(audiopath)\n",
            "  File \"/content/ibibio-tts/codes/models/audio/tts/tacotron2/taco_utils.py\", line 17, in load_wav_to_torch\n",
            "    sampling_rate, data = read(full_path)\n",
            "  File \"/usr/local/lib/python3.10/dist-packages/scipy/io/wavfile.py\", line 647, in read\n",
            "    fid = open(filename, 'rb')\n",
            "FileNotFoundError: [Errno 2] No such file or directory: '/content/drive/MyDrive/dataset/wav_split/wavs//content/drive/MyDrive/dataset/wav/458.wav'\n",
            "\n",
            "During handling of the above exception, another exception occurred:\n",
            "\n",
            "Traceback (most recent call last):\n",
            "  File \"/content/ibibio-tts/codes/data/audio/paired_voice_audio_dataset.py\", line 194, in __getitem__\n",
            "    tseq, wav, text, path, type = self.get_wav_text_pair(self.audiopaths_and_text[index])\n",
            "  File \"/content/ibibio-tts/codes/data/audio/paired_voice_audio_dataset.py\", line 178, in get_wav_text_pair\n",
            "    wav = load_audio(audiopath, self.sample_rate)\n",
            "  File \"/content/ibibio-tts/codes/data/audio/unsupervised_audio_dataset.py\", line 19, in load_audio\n",
            "    audio, lsr = load_wav_to_torch(audiopath)\n",
            "  File \"/content/ibibio-tts/codes/models/audio/tts/tacotron2/taco_utils.py\", line 17, in load_wav_to_torch\n",
            "    sampling_rate, data = read(full_path)\n",
            "  File \"/usr/local/lib/python3.10/dist-packages/scipy/io/wavfile.py\", line 647, in read\n",
            "    fid = open(filename, 'rb')\n",
            "FileNotFoundError: [Errno 2] No such file or directory: '/content/drive/MyDrive/dataset/wav_split/wavs//content/drive/MyDrive/dataset/wav/449.wav'\n",
            "\n",
            "During handling of the above exception, another exception occurred:\n",
            "\n",
            "Traceback (most recent call last):\n",
            "  File \"/content/ibibio-tts/codes/data/audio/paired_voice_audio_dataset.py\", line 194, in __getitem__\n",
            "    tseq, wav, text, path, type = self.get_wav_text_pair(self.audiopaths_and_text[index])\n",
            "  File \"/content/ibibio-tts/codes/data/audio/paired_voice_audio_dataset.py\", line 177, in get_wav_text_pair\n",
            "    text_seq = self.get_text(text)\n",
            "  File \"/content/ibibio-tts/codes/data/audio/paired_voice_audio_dataset.py\", line 186, in get_text\n",
            "    assert not torch.any(tokens == 1)\n",
            "AssertionError\n",
            "\n",
            "During handling of the above exception, another exception occurred:\n",
            "\n",
            "Traceback (most recent call last):\n",
            "  File \"/content/ibibio-tts/codes/data/audio/paired_voice_audio_dataset.py\", line 194, in __getitem__\n",
            "    tseq, wav, text, path, type = self.get_wav_text_pair(self.audiopaths_and_text[index])\n",
            "  File \"/content/ibibio-tts/codes/data/audio/paired_voice_audio_dataset.py\", line 178, in get_wav_text_pair\n",
            "    wav = load_audio(audiopath, self.sample_rate)\n",
            "  File \"/content/ibibio-tts/codes/data/audio/unsupervised_audio_dataset.py\", line 19, in load_audio\n",
            "    audio, lsr = load_wav_to_torch(audiopath)\n",
            "  File \"/content/ibibio-tts/codes/models/audio/tts/tacotron2/taco_utils.py\", line 17, in load_wav_to_torch\n",
            "    sampling_rate, data = read(full_path)\n",
            "  File \"/usr/local/lib/python3.10/dist-packages/scipy/io/wavfile.py\", line 647, in read\n",
            "    fid = open(filename, 'rb')\n",
            "FileNotFoundError: [Errno 2] No such file or directory: '/content/drive/MyDrive/dataset/wav_split/wavs//content/drive/MyDrive/dataset/wav/472.wav'\n",
            "\n",
            "During handling of the above exception, another exception occurred:\n",
            "\n",
            "Traceback (most recent call last):\n",
            "  File \"/content/ibibio-tts/codes/data/audio/paired_voice_audio_dataset.py\", line 194, in __getitem__\n",
            "    tseq, wav, text, path, type = self.get_wav_text_pair(self.audiopaths_and_text[index])\n",
            "  File \"/content/ibibio-tts/codes/data/audio/paired_voice_audio_dataset.py\", line 177, in get_wav_text_pair\n",
            "    text_seq = self.get_text(text)\n",
            "  File \"/content/ibibio-tts/codes/data/audio/paired_voice_audio_dataset.py\", line 186, in get_text\n",
            "    assert not torch.any(tokens == 1)\n",
            "AssertionError\n",
            "\n",
            "During handling of the above exception, another exception occurred:\n",
            "\n",
            "Traceback (most recent call last):\n",
            "  File \"/content/ibibio-tts/codes/data/audio/paired_voice_audio_dataset.py\", line 194, in __getitem__\n",
            "    tseq, wav, text, path, type = self.get_wav_text_pair(self.audiopaths_and_text[index])\n",
            "  File \"/content/ibibio-tts/codes/data/audio/paired_voice_audio_dataset.py\", line 178, in get_wav_text_pair\n",
            "    wav = load_audio(audiopath, self.sample_rate)\n",
            "  File \"/content/ibibio-tts/codes/data/audio/unsupervised_audio_dataset.py\", line 19, in load_audio\n",
            "    audio, lsr = load_wav_to_torch(audiopath)\n",
            "  File \"/content/ibibio-tts/codes/models/audio/tts/tacotron2/taco_utils.py\", line 17, in load_wav_to_torch\n",
            "    sampling_rate, data = read(full_path)\n",
            "  File \"/usr/local/lib/python3.10/dist-packages/scipy/io/wavfile.py\", line 647, in read\n",
            "    fid = open(filename, 'rb')\n",
            "FileNotFoundError: [Errno 2] No such file or directory: '/content/drive/MyDrive/dataset/wav_split/wavs//content/drive/MyDrive/dataset/wav/45.wav'\n",
            "\n",
            "During handling of the above exception, another exception occurred:\n",
            "\n",
            "Traceback (most recent call last):\n",
            "  File \"/content/ibibio-tts/codes/data/audio/paired_voice_audio_dataset.py\", line 194, in __getitem__\n",
            "    tseq, wav, text, path, type = self.get_wav_text_pair(self.audiopaths_and_text[index])\n",
            "  File \"/content/ibibio-tts/codes/data/audio/paired_voice_audio_dataset.py\", line 178, in get_wav_text_pair\n",
            "    wav = load_audio(audiopath, self.sample_rate)\n",
            "  File \"/content/ibibio-tts/codes/data/audio/unsupervised_audio_dataset.py\", line 19, in load_audio\n",
            "    audio, lsr = load_wav_to_torch(audiopath)\n",
            "  File \"/content/ibibio-tts/codes/models/audio/tts/tacotron2/taco_utils.py\", line 17, in load_wav_to_torch\n",
            "    sampling_rate, data = read(full_path)\n",
            "  File \"/usr/local/lib/python3.10/dist-packages/scipy/io/wavfile.py\", line 647, in read\n",
            "    fid = open(filename, 'rb')\n",
            "FileNotFoundError: [Errno 2] No such file or directory: '/content/drive/MyDrive/dataset/wav_split/wavs//content/drive/MyDrive/dataset/wav/206.wav'\n",
            "\n",
            "During handling of the above exception, another exception occurred:\n",
            "\n",
            "Traceback (most recent call last):\n",
            "  File \"/content/ibibio-tts/codes/data/audio/paired_voice_audio_dataset.py\", line 194, in __getitem__\n",
            "    tseq, wav, text, path, type = self.get_wav_text_pair(self.audiopaths_and_text[index])\n",
            "  File \"/content/ibibio-tts/codes/data/audio/paired_voice_audio_dataset.py\", line 178, in get_wav_text_pair\n",
            "    wav = load_audio(audiopath, self.sample_rate)\n",
            "  File \"/content/ibibio-tts/codes/data/audio/unsupervised_audio_dataset.py\", line 19, in load_audio\n",
            "    audio, lsr = load_wav_to_torch(audiopath)\n",
            "  File \"/content/ibibio-tts/codes/models/audio/tts/tacotron2/taco_utils.py\", line 17, in load_wav_to_torch\n",
            "    sampling_rate, data = read(full_path)\n",
            "  File \"/usr/local/lib/python3.10/dist-packages/scipy/io/wavfile.py\", line 647, in read\n",
            "    fid = open(filename, 'rb')\n",
            "FileNotFoundError: [Errno 2] No such file or directory: '/content/drive/MyDrive/dataset/wav_split/wavs//content/drive/MyDrive/dataset/wav/561.wav'\n",
            "\n",
            "During handling of the above exception, another exception occurred:\n",
            "\n",
            "Traceback (most recent call last):\n",
            "  File \"/content/ibibio-tts/codes/data/audio/paired_voice_audio_dataset.py\", line 194, in __getitem__\n",
            "    tseq, wav, text, path, type = self.get_wav_text_pair(self.audiopaths_and_text[index])\n",
            "  File \"/content/ibibio-tts/codes/data/audio/paired_voice_audio_dataset.py\", line 178, in get_wav_text_pair\n",
            "    wav = load_audio(audiopath, self.sample_rate)\n",
            "  File \"/content/ibibio-tts/codes/data/audio/unsupervised_audio_dataset.py\", line 19, in load_audio\n",
            "    audio, lsr = load_wav_to_torch(audiopath)\n",
            "  File \"/content/ibibio-tts/codes/models/audio/tts/tacotron2/taco_utils.py\", line 17, in load_wav_to_torch\n",
            "    sampling_rate, data = read(full_path)\n",
            "  File \"/usr/local/lib/python3.10/dist-packages/scipy/io/wavfile.py\", line 647, in read\n",
            "    fid = open(filename, 'rb')\n",
            "FileNotFoundError: [Errno 2] No such file or directory: '/content/drive/MyDrive/dataset/wav_split/wavs//content/drive/MyDrive/dataset/wav/406.wav'\n",
            "\n",
            "During handling of the above exception, another exception occurred:\n",
            "\n",
            "Traceback (most recent call last):\n",
            "  File \"/content/ibibio-tts/codes/data/audio/paired_voice_audio_dataset.py\", line 194, in __getitem__\n",
            "    tseq, wav, text, path, type = self.get_wav_text_pair(self.audiopaths_and_text[index])\n",
            "  File \"/content/ibibio-tts/codes/data/audio/paired_voice_audio_dataset.py\", line 178, in get_wav_text_pair\n",
            "    wav = load_audio(audiopath, self.sample_rate)\n",
            "  File \"/content/ibibio-tts/codes/data/audio/unsupervised_audio_dataset.py\", line 19, in load_audio\n",
            "    audio, lsr = load_wav_to_torch(audiopath)\n",
            "  File \"/content/ibibio-tts/codes/models/audio/tts/tacotron2/taco_utils.py\", line 17, in load_wav_to_torch\n",
            "    sampling_rate, data = read(full_path)\n",
            "  File \"/usr/local/lib/python3.10/dist-packages/scipy/io/wavfile.py\", line 647, in read\n",
            "    fid = open(filename, 'rb')\n",
            "FileNotFoundError: [Errno 2] No such file or directory: '/content/drive/MyDrive/dataset/wav_split/wavs//content/drive/MyDrive/dataset/wav/72.wav'\n",
            "\n",
            "During handling of the above exception, another exception occurred:\n",
            "\n",
            "Traceback (most recent call last):\n",
            "  File \"/content/ibibio-tts/codes/data/audio/paired_voice_audio_dataset.py\", line 194, in __getitem__\n",
            "    tseq, wav, text, path, type = self.get_wav_text_pair(self.audiopaths_and_text[index])\n",
            "  File \"/content/ibibio-tts/codes/data/audio/paired_voice_audio_dataset.py\", line 178, in get_wav_text_pair\n",
            "    wav = load_audio(audiopath, self.sample_rate)\n",
            "  File \"/content/ibibio-tts/codes/data/audio/unsupervised_audio_dataset.py\", line 19, in load_audio\n",
            "    audio, lsr = load_wav_to_torch(audiopath)\n",
            "  File \"/content/ibibio-tts/codes/models/audio/tts/tacotron2/taco_utils.py\", line 17, in load_wav_to_torch\n",
            "    sampling_rate, data = read(full_path)\n",
            "  File \"/usr/local/lib/python3.10/dist-packages/scipy/io/wavfile.py\", line 647, in read\n",
            "    fid = open(filename, 'rb')\n",
            "FileNotFoundError: [Errno 2] No such file or directory: '/content/drive/MyDrive/dataset/wav_split/wavs//content/drive/MyDrive/dataset/wav/356.wav'\n",
            "\n",
            "During handling of the above exception, another exception occurred:\n",
            "\n",
            "Traceback (most recent call last):\n",
            "  File \"/content/ibibio-tts/codes/data/audio/paired_voice_audio_dataset.py\", line 194, in __getitem__\n",
            "    tseq, wav, text, path, type = self.get_wav_text_pair(self.audiopaths_and_text[index])\n",
            "  File \"/content/ibibio-tts/codes/data/audio/paired_voice_audio_dataset.py\", line 178, in get_wav_text_pair\n",
            "    wav = load_audio(audiopath, self.sample_rate)\n",
            "  File \"/content/ibibio-tts/codes/data/audio/unsupervised_audio_dataset.py\", line 19, in load_audio\n",
            "    audio, lsr = load_wav_to_torch(audiopath)\n",
            "  File \"/content/ibibio-tts/codes/models/audio/tts/tacotron2/taco_utils.py\", line 17, in load_wav_to_torch\n",
            "    sampling_rate, data = read(full_path)\n",
            "  File \"/usr/local/lib/python3.10/dist-packages/scipy/io/wavfile.py\", line 647, in read\n",
            "    fid = open(filename, 'rb')\n",
            "FileNotFoundError: [Errno 2] No such file or directory: '/content/drive/MyDrive/dataset/wav_split/wavs//content/drive/MyDrive/dataset/wav/399.wav'\n",
            "\n",
            "During handling of the above exception, another exception occurred:\n",
            "\n",
            "Traceback (most recent call last):\n",
            "  File \"/content/ibibio-tts/codes/data/audio/paired_voice_audio_dataset.py\", line 194, in __getitem__\n",
            "    tseq, wav, text, path, type = self.get_wav_text_pair(self.audiopaths_and_text[index])\n",
            "  File \"/content/ibibio-tts/codes/data/audio/paired_voice_audio_dataset.py\", line 178, in get_wav_text_pair\n",
            "    wav = load_audio(audiopath, self.sample_rate)\n",
            "  File \"/content/ibibio-tts/codes/data/audio/unsupervised_audio_dataset.py\", line 19, in load_audio\n",
            "    audio, lsr = load_wav_to_torch(audiopath)\n",
            "  File \"/content/ibibio-tts/codes/models/audio/tts/tacotron2/taco_utils.py\", line 17, in load_wav_to_torch\n",
            "    sampling_rate, data = read(full_path)\n",
            "  File \"/usr/local/lib/python3.10/dist-packages/scipy/io/wavfile.py\", line 647, in read\n",
            "    fid = open(filename, 'rb')\n",
            "FileNotFoundError: [Errno 2] No such file or directory: '/content/drive/MyDrive/dataset/wav_split/wavs//content/drive/MyDrive/dataset/wav/539.wav'\n",
            "\n",
            "During handling of the above exception, another exception occurred:\n",
            "\n",
            "Traceback (most recent call last):\n",
            "  File \"/content/ibibio-tts/codes/data/audio/paired_voice_audio_dataset.py\", line 194, in __getitem__\n",
            "    tseq, wav, text, path, type = self.get_wav_text_pair(self.audiopaths_and_text[index])\n",
            "  File \"/content/ibibio-tts/codes/data/audio/paired_voice_audio_dataset.py\", line 178, in get_wav_text_pair\n",
            "    wav = load_audio(audiopath, self.sample_rate)\n",
            "  File \"/content/ibibio-tts/codes/data/audio/unsupervised_audio_dataset.py\", line 19, in load_audio\n",
            "    audio, lsr = load_wav_to_torch(audiopath)\n",
            "  File \"/content/ibibio-tts/codes/models/audio/tts/tacotron2/taco_utils.py\", line 17, in load_wav_to_torch\n",
            "    sampling_rate, data = read(full_path)\n",
            "  File \"/usr/local/lib/python3.10/dist-packages/scipy/io/wavfile.py\", line 647, in read\n",
            "    fid = open(filename, 'rb')\n",
            "FileNotFoundError: [Errno 2] No such file or directory: '/content/drive/MyDrive/dataset/wav_split/wavs//content/drive/MyDrive/dataset/wav/46.wav'\n",
            "\n",
            "During handling of the above exception, another exception occurred:\n",
            "\n",
            "Traceback (most recent call last):\n",
            "  File \"/content/ibibio-tts/codes/data/audio/paired_voice_audio_dataset.py\", line 194, in __getitem__\n",
            "    tseq, wav, text, path, type = self.get_wav_text_pair(self.audiopaths_and_text[index])\n",
            "  File \"/content/ibibio-tts/codes/data/audio/paired_voice_audio_dataset.py\", line 178, in get_wav_text_pair\n",
            "    wav = load_audio(audiopath, self.sample_rate)\n",
            "  File \"/content/ibibio-tts/codes/data/audio/unsupervised_audio_dataset.py\", line 19, in load_audio\n",
            "    audio, lsr = load_wav_to_torch(audiopath)\n",
            "  File \"/content/ibibio-tts/codes/models/audio/tts/tacotron2/taco_utils.py\", line 17, in load_wav_to_torch\n",
            "    sampling_rate, data = read(full_path)\n",
            "  File \"/usr/local/lib/python3.10/dist-packages/scipy/io/wavfile.py\", line 647, in read\n",
            "    fid = open(filename, 'rb')\n",
            "FileNotFoundError: [Errno 2] No such file or directory: '/content/drive/MyDrive/dataset/wav_split/wavs//content/drive/MyDrive/dataset/wav/178.wav'\n",
            "\n",
            "During handling of the above exception, another exception occurred:\n",
            "\n",
            "Traceback (most recent call last):\n",
            "  File \"/content/ibibio-tts/codes/data/audio/paired_voice_audio_dataset.py\", line 194, in __getitem__\n",
            "    tseq, wav, text, path, type = self.get_wav_text_pair(self.audiopaths_and_text[index])\n",
            "  File \"/content/ibibio-tts/codes/data/audio/paired_voice_audio_dataset.py\", line 178, in get_wav_text_pair\n",
            "    wav = load_audio(audiopath, self.sample_rate)\n",
            "  File \"/content/ibibio-tts/codes/data/audio/unsupervised_audio_dataset.py\", line 19, in load_audio\n",
            "    audio, lsr = load_wav_to_torch(audiopath)\n",
            "  File \"/content/ibibio-tts/codes/models/audio/tts/tacotron2/taco_utils.py\", line 17, in load_wav_to_torch\n",
            "    sampling_rate, data = read(full_path)\n",
            "  File \"/usr/local/lib/python3.10/dist-packages/scipy/io/wavfile.py\", line 647, in read\n",
            "    fid = open(filename, 'rb')\n",
            "FileNotFoundError: [Errno 2] No such file or directory: '/content/drive/MyDrive/dataset/wav_split/wavs//content/drive/MyDrive/dataset/wav/542.wav'\n",
            "\n",
            "During handling of the above exception, another exception occurred:\n",
            "\n",
            "Traceback (most recent call last):\n",
            "  File \"/content/ibibio-tts/codes/data/audio/paired_voice_audio_dataset.py\", line 194, in __getitem__\n",
            "    tseq, wav, text, path, type = self.get_wav_text_pair(self.audiopaths_and_text[index])\n",
            "  File \"/content/ibibio-tts/codes/data/audio/paired_voice_audio_dataset.py\", line 177, in get_wav_text_pair\n",
            "    text_seq = self.get_text(text)\n",
            "  File \"/content/ibibio-tts/codes/data/audio/paired_voice_audio_dataset.py\", line 186, in get_text\n",
            "    assert not torch.any(tokens == 1)\n",
            "AssertionError\n",
            "\n",
            "During handling of the above exception, another exception occurred:\n",
            "\n",
            "Traceback (most recent call last):\n",
            "  File \"/content/ibibio-tts/codes/data/audio/paired_voice_audio_dataset.py\", line 194, in __getitem__\n",
            "    tseq, wav, text, path, type = self.get_wav_text_pair(self.audiopaths_and_text[index])\n",
            "  File \"/content/ibibio-tts/codes/data/audio/paired_voice_audio_dataset.py\", line 177, in get_wav_text_pair\n",
            "    text_seq = self.get_text(text)\n",
            "  File \"/content/ibibio-tts/codes/data/audio/paired_voice_audio_dataset.py\", line 186, in get_text\n",
            "    assert not torch.any(tokens == 1)\n",
            "AssertionError\n",
            "\n",
            "During handling of the above exception, another exception occurred:\n",
            "\n",
            "Traceback (most recent call last):\n",
            "  File \"/content/ibibio-tts/codes/data/audio/paired_voice_audio_dataset.py\", line 194, in __getitem__\n",
            "    tseq, wav, text, path, type = self.get_wav_text_pair(self.audiopaths_and_text[index])\n",
            "  File \"/content/ibibio-tts/codes/data/audio/paired_voice_audio_dataset.py\", line 177, in get_wav_text_pair\n",
            "    text_seq = self.get_text(text)\n",
            "  File \"/content/ibibio-tts/codes/data/audio/paired_voice_audio_dataset.py\", line 186, in get_text\n",
            "    assert not torch.any(tokens == 1)\n",
            "AssertionError\n",
            "\n",
            "During handling of the above exception, another exception occurred:\n",
            "\n",
            "Traceback (most recent call last):\n",
            "  File \"/content/ibibio-tts/codes/data/audio/paired_voice_audio_dataset.py\", line 194, in __getitem__\n",
            "    tseq, wav, text, path, type = self.get_wav_text_pair(self.audiopaths_and_text[index])\n",
            "  File \"/content/ibibio-tts/codes/data/audio/paired_voice_audio_dataset.py\", line 178, in get_wav_text_pair\n",
            "    wav = load_audio(audiopath, self.sample_rate)\n",
            "  File \"/content/ibibio-tts/codes/data/audio/unsupervised_audio_dataset.py\", line 19, in load_audio\n",
            "    audio, lsr = load_wav_to_torch(audiopath)\n",
            "  File \"/content/ibibio-tts/codes/models/audio/tts/tacotron2/taco_utils.py\", line 17, in load_wav_to_torch\n",
            "    sampling_rate, data = read(full_path)\n",
            "  File \"/usr/local/lib/python3.10/dist-packages/scipy/io/wavfile.py\", line 647, in read\n",
            "    fid = open(filename, 'rb')\n",
            "FileNotFoundError: [Errno 2] No such file or directory: '/content/drive/MyDrive/dataset/wav_split/wavs//content/drive/MyDrive/dataset/wav/16.wav'\n",
            "\n",
            "During handling of the above exception, another exception occurred:\n",
            "\n",
            "Traceback (most recent call last):\n",
            "  File \"/content/ibibio-tts/codes/data/audio/paired_voice_audio_dataset.py\", line 194, in __getitem__\n",
            "    tseq, wav, text, path, type = self.get_wav_text_pair(self.audiopaths_and_text[index])\n",
            "  File \"/content/ibibio-tts/codes/data/audio/paired_voice_audio_dataset.py\", line 178, in get_wav_text_pair\n",
            "    wav = load_audio(audiopath, self.sample_rate)\n",
            "  File \"/content/ibibio-tts/codes/data/audio/unsupervised_audio_dataset.py\", line 19, in load_audio\n",
            "    audio, lsr = load_wav_to_torch(audiopath)\n",
            "  File \"/content/ibibio-tts/codes/models/audio/tts/tacotron2/taco_utils.py\", line 17, in load_wav_to_torch\n",
            "    sampling_rate, data = read(full_path)\n",
            "  File \"/usr/local/lib/python3.10/dist-packages/scipy/io/wavfile.py\", line 647, in read\n",
            "    fid = open(filename, 'rb')\n",
            "FileNotFoundError: [Errno 2] No such file or directory: '/content/drive/MyDrive/dataset/wav_split/wavs//content/drive/MyDrive/dataset/wav/586.wav'\n",
            "\n",
            "During handling of the above exception, another exception occurred:\n",
            "\n",
            "Traceback (most recent call last):\n",
            "  File \"/content/ibibio-tts/codes/data/audio/paired_voice_audio_dataset.py\", line 194, in __getitem__\n",
            "    tseq, wav, text, path, type = self.get_wav_text_pair(self.audiopaths_and_text[index])\n",
            "  File \"/content/ibibio-tts/codes/data/audio/paired_voice_audio_dataset.py\", line 177, in get_wav_text_pair\n",
            "    text_seq = self.get_text(text)\n",
            "  File \"/content/ibibio-tts/codes/data/audio/paired_voice_audio_dataset.py\", line 186, in get_text\n",
            "    assert not torch.any(tokens == 1)\n",
            "AssertionError\n",
            "\n",
            "During handling of the above exception, another exception occurred:\n",
            "\n",
            "Traceback (most recent call last):\n",
            "  File \"/content/ibibio-tts/codes/data/audio/paired_voice_audio_dataset.py\", line 194, in __getitem__\n",
            "    tseq, wav, text, path, type = self.get_wav_text_pair(self.audiopaths_and_text[index])\n",
            "  File \"/content/ibibio-tts/codes/data/audio/paired_voice_audio_dataset.py\", line 178, in get_wav_text_pair\n",
            "    wav = load_audio(audiopath, self.sample_rate)\n",
            "  File \"/content/ibibio-tts/codes/data/audio/unsupervised_audio_dataset.py\", line 19, in load_audio\n",
            "    audio, lsr = load_wav_to_torch(audiopath)\n",
            "  File \"/content/ibibio-tts/codes/models/audio/tts/tacotron2/taco_utils.py\", line 17, in load_wav_to_torch\n",
            "    sampling_rate, data = read(full_path)\n",
            "  File \"/usr/local/lib/python3.10/dist-packages/scipy/io/wavfile.py\", line 647, in read\n",
            "    fid = open(filename, 'rb')\n",
            "FileNotFoundError: [Errno 2] No such file or directory: '/content/drive/MyDrive/dataset/wav_split/wavs//content/drive/MyDrive/dataset/wav/284.wav'\n",
            "\n",
            "During handling of the above exception, another exception occurred:\n",
            "\n",
            "Traceback (most recent call last):\n",
            "  File \"/content/ibibio-tts/codes/data/audio/paired_voice_audio_dataset.py\", line 194, in __getitem__\n",
            "    tseq, wav, text, path, type = self.get_wav_text_pair(self.audiopaths_and_text[index])\n",
            "  File \"/content/ibibio-tts/codes/data/audio/paired_voice_audio_dataset.py\", line 178, in get_wav_text_pair\n",
            "    wav = load_audio(audiopath, self.sample_rate)\n",
            "  File \"/content/ibibio-tts/codes/data/audio/unsupervised_audio_dataset.py\", line 19, in load_audio\n",
            "    audio, lsr = load_wav_to_torch(audiopath)\n",
            "  File \"/content/ibibio-tts/codes/models/audio/tts/tacotron2/taco_utils.py\", line 17, in load_wav_to_torch\n",
            "    sampling_rate, data = read(full_path)\n",
            "  File \"/usr/local/lib/python3.10/dist-packages/scipy/io/wavfile.py\", line 647, in read\n",
            "    fid = open(filename, 'rb')\n",
            "FileNotFoundError: [Errno 2] No such file or directory: '/content/drive/MyDrive/dataset/wav_split/wavs//content/drive/MyDrive/dataset/wav/14.wav'\n",
            "\n",
            "During handling of the above exception, another exception occurred:\n",
            "\n",
            "Traceback (most recent call last):\n",
            "  File \"/content/ibibio-tts/codes/data/audio/paired_voice_audio_dataset.py\", line 194, in __getitem__\n",
            "    tseq, wav, text, path, type = self.get_wav_text_pair(self.audiopaths_and_text[index])\n",
            "  File \"/content/ibibio-tts/codes/data/audio/paired_voice_audio_dataset.py\", line 178, in get_wav_text_pair\n",
            "    wav = load_audio(audiopath, self.sample_rate)\n",
            "  File \"/content/ibibio-tts/codes/data/audio/unsupervised_audio_dataset.py\", line 19, in load_audio\n",
            "    audio, lsr = load_wav_to_torch(audiopath)\n",
            "  File \"/content/ibibio-tts/codes/models/audio/tts/tacotron2/taco_utils.py\", line 17, in load_wav_to_torch\n",
            "    sampling_rate, data = read(full_path)\n",
            "  File \"/usr/local/lib/python3.10/dist-packages/scipy/io/wavfile.py\", line 647, in read\n",
            "    fid = open(filename, 'rb')\n",
            "FileNotFoundError: [Errno 2] No such file or directory: '/content/drive/MyDrive/dataset/wav_split/wavs//content/drive/MyDrive/dataset/wav/647.wav'\n",
            "\n",
            "During handling of the above exception, another exception occurred:\n",
            "\n",
            "Traceback (most recent call last):\n",
            "  File \"/content/ibibio-tts/codes/data/audio/paired_voice_audio_dataset.py\", line 194, in __getitem__\n",
            "    tseq, wav, text, path, type = self.get_wav_text_pair(self.audiopaths_and_text[index])\n",
            "  File \"/content/ibibio-tts/codes/data/audio/paired_voice_audio_dataset.py\", line 178, in get_wav_text_pair\n",
            "    wav = load_audio(audiopath, self.sample_rate)\n",
            "  File \"/content/ibibio-tts/codes/data/audio/unsupervised_audio_dataset.py\", line 19, in load_audio\n",
            "    audio, lsr = load_wav_to_torch(audiopath)\n",
            "  File \"/content/ibibio-tts/codes/models/audio/tts/tacotron2/taco_utils.py\", line 17, in load_wav_to_torch\n",
            "    sampling_rate, data = read(full_path)\n",
            "  File \"/usr/local/lib/python3.10/dist-packages/scipy/io/wavfile.py\", line 647, in read\n",
            "    fid = open(filename, 'rb')\n",
            "FileNotFoundError: [Errno 2] No such file or directory: '/content/drive/MyDrive/dataset/wav_split/wavs//content/drive/MyDrive/dataset/wav/443.wav'\n",
            "\n",
            "During handling of the above exception, another exception occurred:\n",
            "\n",
            "Traceback (most recent call last):\n",
            "  File \"/content/ibibio-tts/codes/data/audio/paired_voice_audio_dataset.py\", line 194, in __getitem__\n",
            "    tseq, wav, text, path, type = self.get_wav_text_pair(self.audiopaths_and_text[index])\n",
            "  File \"/content/ibibio-tts/codes/data/audio/paired_voice_audio_dataset.py\", line 177, in get_wav_text_pair\n",
            "    text_seq = self.get_text(text)\n",
            "  File \"/content/ibibio-tts/codes/data/audio/paired_voice_audio_dataset.py\", line 186, in get_text\n",
            "    assert not torch.any(tokens == 1)\n",
            "AssertionError\n",
            "\n",
            "During handling of the above exception, another exception occurred:\n",
            "\n",
            "Traceback (most recent call last):\n",
            "  File \"/content/ibibio-tts/codes/data/audio/paired_voice_audio_dataset.py\", line 194, in __getitem__\n",
            "    tseq, wav, text, path, type = self.get_wav_text_pair(self.audiopaths_and_text[index])\n",
            "  File \"/content/ibibio-tts/codes/data/audio/paired_voice_audio_dataset.py\", line 178, in get_wav_text_pair\n",
            "    wav = load_audio(audiopath, self.sample_rate)\n",
            "  File \"/content/ibibio-tts/codes/data/audio/unsupervised_audio_dataset.py\", line 19, in load_audio\n",
            "    audio, lsr = load_wav_to_torch(audiopath)\n",
            "  File \"/content/ibibio-tts/codes/models/audio/tts/tacotron2/taco_utils.py\", line 17, in load_wav_to_torch\n",
            "    sampling_rate, data = read(full_path)\n",
            "  File \"/usr/local/lib/python3.10/dist-packages/scipy/io/wavfile.py\", line 647, in read\n",
            "    fid = open(filename, 'rb')\n",
            "FileNotFoundError: [Errno 2] No such file or directory: '/content/drive/MyDrive/dataset/wav_split/wavs//content/drive/MyDrive/dataset/wav/226.wav'\n",
            "\n",
            "During handling of the above exception, another exception occurred:\n",
            "\n",
            "Traceback (most recent call last):\n",
            "  File \"/content/ibibio-tts/codes/data/audio/paired_voice_audio_dataset.py\", line 194, in __getitem__\n",
            "    tseq, wav, text, path, type = self.get_wav_text_pair(self.audiopaths_and_text[index])\n",
            "  File \"/content/ibibio-tts/codes/data/audio/paired_voice_audio_dataset.py\", line 178, in get_wav_text_pair\n",
            "    wav = load_audio(audiopath, self.sample_rate)\n",
            "  File \"/content/ibibio-tts/codes/data/audio/unsupervised_audio_dataset.py\", line 19, in load_audio\n",
            "    audio, lsr = load_wav_to_torch(audiopath)\n",
            "  File \"/content/ibibio-tts/codes/models/audio/tts/tacotron2/taco_utils.py\", line 17, in load_wav_to_torch\n",
            "    sampling_rate, data = read(full_path)\n",
            "  File \"/usr/local/lib/python3.10/dist-packages/scipy/io/wavfile.py\", line 647, in read\n",
            "    fid = open(filename, 'rb')\n",
            "FileNotFoundError: [Errno 2] No such file or directory: '/content/drive/MyDrive/dataset/wav_split/wavs//content/drive/MyDrive/dataset/wav/577.wav'\n",
            "\n",
            "During handling of the above exception, another exception occurred:\n",
            "\n",
            "Traceback (most recent call last):\n",
            "  File \"/content/ibibio-tts/codes/data/audio/paired_voice_audio_dataset.py\", line 194, in __getitem__\n",
            "    tseq, wav, text, path, type = self.get_wav_text_pair(self.audiopaths_and_text[index])\n",
            "  File \"/content/ibibio-tts/codes/data/audio/paired_voice_audio_dataset.py\", line 178, in get_wav_text_pair\n",
            "    wav = load_audio(audiopath, self.sample_rate)\n",
            "  File \"/content/ibibio-tts/codes/data/audio/unsupervised_audio_dataset.py\", line 19, in load_audio\n",
            "    audio, lsr = load_wav_to_torch(audiopath)\n",
            "  File \"/content/ibibio-tts/codes/models/audio/tts/tacotron2/taco_utils.py\", line 17, in load_wav_to_torch\n",
            "    sampling_rate, data = read(full_path)\n",
            "  File \"/usr/local/lib/python3.10/dist-packages/scipy/io/wavfile.py\", line 647, in read\n",
            "    fid = open(filename, 'rb')\n",
            "FileNotFoundError: [Errno 2] No such file or directory: '/content/drive/MyDrive/dataset/wav_split/wavs//content/drive/MyDrive/dataset/wav/261.wav'\n",
            "\n",
            "During handling of the above exception, another exception occurred:\n",
            "\n",
            "Traceback (most recent call last):\n",
            "  File \"/content/ibibio-tts/codes/data/audio/paired_voice_audio_dataset.py\", line 194, in __getitem__\n",
            "    tseq, wav, text, path, type = self.get_wav_text_pair(self.audiopaths_and_text[index])\n",
            "  File \"/content/ibibio-tts/codes/data/audio/paired_voice_audio_dataset.py\", line 177, in get_wav_text_pair\n",
            "    text_seq = self.get_text(text)\n",
            "  File \"/content/ibibio-tts/codes/data/audio/paired_voice_audio_dataset.py\", line 186, in get_text\n",
            "    assert not torch.any(tokens == 1)\n",
            "AssertionError\n",
            "\n",
            "During handling of the above exception, another exception occurred:\n",
            "\n",
            "Traceback (most recent call last):\n",
            "  File \"/content/ibibio-tts/codes/data/audio/paired_voice_audio_dataset.py\", line 194, in __getitem__\n",
            "    tseq, wav, text, path, type = self.get_wav_text_pair(self.audiopaths_and_text[index])\n",
            "  File \"/content/ibibio-tts/codes/data/audio/paired_voice_audio_dataset.py\", line 178, in get_wav_text_pair\n",
            "    wav = load_audio(audiopath, self.sample_rate)\n",
            "  File \"/content/ibibio-tts/codes/data/audio/unsupervised_audio_dataset.py\", line 19, in load_audio\n",
            "    audio, lsr = load_wav_to_torch(audiopath)\n",
            "  File \"/content/ibibio-tts/codes/models/audio/tts/tacotron2/taco_utils.py\", line 17, in load_wav_to_torch\n",
            "    sampling_rate, data = read(full_path)\n",
            "  File \"/usr/local/lib/python3.10/dist-packages/scipy/io/wavfile.py\", line 647, in read\n",
            "    fid = open(filename, 'rb')\n",
            "FileNotFoundError: [Errno 2] No such file or directory: '/content/drive/MyDrive/dataset/wav_split/wavs//content/drive/MyDrive/dataset/wav/36.wav'\n",
            "\n",
            "During handling of the above exception, another exception occurred:\n",
            "\n",
            "Traceback (most recent call last):\n",
            "  File \"/content/ibibio-tts/codes/data/audio/paired_voice_audio_dataset.py\", line 194, in __getitem__\n",
            "    tseq, wav, text, path, type = self.get_wav_text_pair(self.audiopaths_and_text[index])\n",
            "  File \"/content/ibibio-tts/codes/data/audio/paired_voice_audio_dataset.py\", line 178, in get_wav_text_pair\n",
            "    wav = load_audio(audiopath, self.sample_rate)\n",
            "  File \"/content/ibibio-tts/codes/data/audio/unsupervised_audio_dataset.py\", line 19, in load_audio\n",
            "    audio, lsr = load_wav_to_torch(audiopath)\n",
            "  File \"/content/ibibio-tts/codes/models/audio/tts/tacotron2/taco_utils.py\", line 17, in load_wav_to_torch\n",
            "    sampling_rate, data = read(full_path)\n",
            "  File \"/usr/local/lib/python3.10/dist-packages/scipy/io/wavfile.py\", line 647, in read\n",
            "    fid = open(filename, 'rb')\n",
            "FileNotFoundError: [Errno 2] No such file or directory: '/content/drive/MyDrive/dataset/wav_split/wavs//content/drive/MyDrive/dataset/wav/548.wav'\n",
            "\n",
            "During handling of the above exception, another exception occurred:\n",
            "\n",
            "Traceback (most recent call last):\n",
            "  File \"/content/ibibio-tts/codes/data/audio/paired_voice_audio_dataset.py\", line 194, in __getitem__\n",
            "    tseq, wav, text, path, type = self.get_wav_text_pair(self.audiopaths_and_text[index])\n",
            "  File \"/content/ibibio-tts/codes/data/audio/paired_voice_audio_dataset.py\", line 178, in get_wav_text_pair\n",
            "    wav = load_audio(audiopath, self.sample_rate)\n",
            "  File \"/content/ibibio-tts/codes/data/audio/unsupervised_audio_dataset.py\", line 19, in load_audio\n",
            "    audio, lsr = load_wav_to_torch(audiopath)\n",
            "  File \"/content/ibibio-tts/codes/models/audio/tts/tacotron2/taco_utils.py\", line 17, in load_wav_to_torch\n",
            "    sampling_rate, data = read(full_path)\n",
            "  File \"/usr/local/lib/python3.10/dist-packages/scipy/io/wavfile.py\", line 647, in read\n",
            "    fid = open(filename, 'rb')\n",
            "FileNotFoundError: [Errno 2] No such file or directory: '/content/drive/MyDrive/dataset/wav_split/wavs//content/drive/MyDrive/dataset/wav/441.wav'\n",
            "\n",
            "During handling of the above exception, another exception occurred:\n",
            "\n",
            "Traceback (most recent call last):\n",
            "  File \"/content/ibibio-tts/codes/data/audio/paired_voice_audio_dataset.py\", line 194, in __getitem__\n",
            "    tseq, wav, text, path, type = self.get_wav_text_pair(self.audiopaths_and_text[index])\n",
            "  File \"/content/ibibio-tts/codes/data/audio/paired_voice_audio_dataset.py\", line 177, in get_wav_text_pair\n",
            "    text_seq = self.get_text(text)\n",
            "  File \"/content/ibibio-tts/codes/data/audio/paired_voice_audio_dataset.py\", line 186, in get_text\n",
            "    assert not torch.any(tokens == 1)\n",
            "AssertionError\n",
            "\n",
            "During handling of the above exception, another exception occurred:\n",
            "\n",
            "Traceback (most recent call last):\n",
            "  File \"/content/ibibio-tts/codes/data/audio/paired_voice_audio_dataset.py\", line 194, in __getitem__\n",
            "    tseq, wav, text, path, type = self.get_wav_text_pair(self.audiopaths_and_text[index])\n",
            "  File \"/content/ibibio-tts/codes/data/audio/paired_voice_audio_dataset.py\", line 177, in get_wav_text_pair\n",
            "    text_seq = self.get_text(text)\n",
            "  File \"/content/ibibio-tts/codes/data/audio/paired_voice_audio_dataset.py\", line 186, in get_text\n",
            "    assert not torch.any(tokens == 1)\n",
            "AssertionError\n",
            "\n",
            "During handling of the above exception, another exception occurred:\n",
            "\n",
            "Traceback (most recent call last):\n",
            "  File \"/content/ibibio-tts/codes/data/audio/paired_voice_audio_dataset.py\", line 194, in __getitem__\n",
            "    tseq, wav, text, path, type = self.get_wav_text_pair(self.audiopaths_and_text[index])\n",
            "  File \"/content/ibibio-tts/codes/data/audio/paired_voice_audio_dataset.py\", line 177, in get_wav_text_pair\n",
            "    text_seq = self.get_text(text)\n",
            "  File \"/content/ibibio-tts/codes/data/audio/paired_voice_audio_dataset.py\", line 186, in get_text\n",
            "    assert not torch.any(tokens == 1)\n",
            "AssertionError\n",
            "\n",
            "During handling of the above exception, another exception occurred:\n",
            "\n",
            "Traceback (most recent call last):\n",
            "  File \"/content/ibibio-tts/codes/data/audio/paired_voice_audio_dataset.py\", line 194, in __getitem__\n",
            "    tseq, wav, text, path, type = self.get_wav_text_pair(self.audiopaths_and_text[index])\n",
            "  File \"/content/ibibio-tts/codes/data/audio/paired_voice_audio_dataset.py\", line 177, in get_wav_text_pair\n",
            "    text_seq = self.get_text(text)\n",
            "  File \"/content/ibibio-tts/codes/data/audio/paired_voice_audio_dataset.py\", line 186, in get_text\n",
            "    assert not torch.any(tokens == 1)\n",
            "AssertionError\n",
            "\n",
            "During handling of the above exception, another exception occurred:\n",
            "\n",
            "Traceback (most recent call last):\n",
            "  File \"/content/ibibio-tts/codes/data/audio/paired_voice_audio_dataset.py\", line 194, in __getitem__\n",
            "    tseq, wav, text, path, type = self.get_wav_text_pair(self.audiopaths_and_text[index])\n",
            "  File \"/content/ibibio-tts/codes/data/audio/paired_voice_audio_dataset.py\", line 178, in get_wav_text_pair\n",
            "    wav = load_audio(audiopath, self.sample_rate)\n",
            "  File \"/content/ibibio-tts/codes/data/audio/unsupervised_audio_dataset.py\", line 19, in load_audio\n",
            "    audio, lsr = load_wav_to_torch(audiopath)\n",
            "  File \"/content/ibibio-tts/codes/models/audio/tts/tacotron2/taco_utils.py\", line 17, in load_wav_to_torch\n",
            "    sampling_rate, data = read(full_path)\n",
            "  File \"/usr/local/lib/python3.10/dist-packages/scipy/io/wavfile.py\", line 647, in read\n",
            "    fid = open(filename, 'rb')\n",
            "FileNotFoundError: [Errno 2] No such file or directory: '/content/drive/MyDrive/dataset/wav_split/wavs//content/drive/MyDrive/dataset/wav/26.wav'\n",
            "\n",
            "During handling of the above exception, another exception occurred:\n",
            "\n",
            "Traceback (most recent call last):\n",
            "  File \"/content/ibibio-tts/codes/data/audio/paired_voice_audio_dataset.py\", line 194, in __getitem__\n",
            "    tseq, wav, text, path, type = self.get_wav_text_pair(self.audiopaths_and_text[index])\n",
            "  File \"/content/ibibio-tts/codes/data/audio/paired_voice_audio_dataset.py\", line 178, in get_wav_text_pair\n",
            "    wav = load_audio(audiopath, self.sample_rate)\n",
            "  File \"/content/ibibio-tts/codes/data/audio/unsupervised_audio_dataset.py\", line 19, in load_audio\n",
            "    audio, lsr = load_wav_to_torch(audiopath)\n",
            "  File \"/content/ibibio-tts/codes/models/audio/tts/tacotron2/taco_utils.py\", line 17, in load_wav_to_torch\n",
            "    sampling_rate, data = read(full_path)\n",
            "  File \"/usr/local/lib/python3.10/dist-packages/scipy/io/wavfile.py\", line 647, in read\n",
            "    fid = open(filename, 'rb')\n",
            "FileNotFoundError: [Errno 2] No such file or directory: '/content/drive/MyDrive/dataset/wav_split/wavs//content/drive/MyDrive/dataset/wav/485.wav'\n",
            "\n",
            "During handling of the above exception, another exception occurred:\n",
            "\n",
            "Traceback (most recent call last):\n",
            "  File \"/content/ibibio-tts/codes/data/audio/paired_voice_audio_dataset.py\", line 194, in __getitem__\n",
            "    tseq, wav, text, path, type = self.get_wav_text_pair(self.audiopaths_and_text[index])\n",
            "  File \"/content/ibibio-tts/codes/data/audio/paired_voice_audio_dataset.py\", line 178, in get_wav_text_pair\n",
            "    wav = load_audio(audiopath, self.sample_rate)\n",
            "  File \"/content/ibibio-tts/codes/data/audio/unsupervised_audio_dataset.py\", line 19, in load_audio\n",
            "    audio, lsr = load_wav_to_torch(audiopath)\n",
            "  File \"/content/ibibio-tts/codes/models/audio/tts/tacotron2/taco_utils.py\", line 17, in load_wav_to_torch\n",
            "    sampling_rate, data = read(full_path)\n",
            "  File \"/usr/local/lib/python3.10/dist-packages/scipy/io/wavfile.py\", line 647, in read\n",
            "    fid = open(filename, 'rb')\n",
            "FileNotFoundError: [Errno 2] No such file or directory: '/content/drive/MyDrive/dataset/wav_split/wavs//content/drive/MyDrive/dataset/wav/17.wav'\n",
            "\n",
            "During handling of the above exception, another exception occurred:\n",
            "\n",
            "Traceback (most recent call last):\n",
            "  File \"/content/ibibio-tts/codes/data/audio/paired_voice_audio_dataset.py\", line 194, in __getitem__\n",
            "    tseq, wav, text, path, type = self.get_wav_text_pair(self.audiopaths_and_text[index])\n",
            "  File \"/content/ibibio-tts/codes/data/audio/paired_voice_audio_dataset.py\", line 178, in get_wav_text_pair\n",
            "    wav = load_audio(audiopath, self.sample_rate)\n",
            "  File \"/content/ibibio-tts/codes/data/audio/unsupervised_audio_dataset.py\", line 19, in load_audio\n",
            "    audio, lsr = load_wav_to_torch(audiopath)\n",
            "  File \"/content/ibibio-tts/codes/models/audio/tts/tacotron2/taco_utils.py\", line 17, in load_wav_to_torch\n",
            "    sampling_rate, data = read(full_path)\n",
            "  File \"/usr/local/lib/python3.10/dist-packages/scipy/io/wavfile.py\", line 647, in read\n",
            "    fid = open(filename, 'rb')\n",
            "FileNotFoundError: [Errno 2] No such file or directory: '/content/drive/MyDrive/dataset/wav_split/wavs//content/drive/MyDrive/dataset/wav/532.wav'\n",
            "\n",
            "During handling of the above exception, another exception occurred:\n",
            "\n",
            "Traceback (most recent call last):\n",
            "  File \"/content/ibibio-tts/codes/data/audio/paired_voice_audio_dataset.py\", line 194, in __getitem__\n",
            "    tseq, wav, text, path, type = self.get_wav_text_pair(self.audiopaths_and_text[index])\n",
            "  File \"/content/ibibio-tts/codes/data/audio/paired_voice_audio_dataset.py\", line 178, in get_wav_text_pair\n",
            "    wav = load_audio(audiopath, self.sample_rate)\n",
            "  File \"/content/ibibio-tts/codes/data/audio/unsupervised_audio_dataset.py\", line 19, in load_audio\n",
            "    audio, lsr = load_wav_to_torch(audiopath)\n",
            "  File \"/content/ibibio-tts/codes/models/audio/tts/tacotron2/taco_utils.py\", line 17, in load_wav_to_torch\n",
            "    sampling_rate, data = read(full_path)\n",
            "  File \"/usr/local/lib/python3.10/dist-packages/scipy/io/wavfile.py\", line 647, in read\n",
            "    fid = open(filename, 'rb')\n",
            "FileNotFoundError: [Errno 2] No such file or directory: '/content/drive/MyDrive/dataset/wav_split/wavs//content/drive/MyDrive/dataset/wav/637.wav'\n",
            "\n",
            "During handling of the above exception, another exception occurred:\n",
            "\n",
            "Traceback (most recent call last):\n",
            "  File \"/content/ibibio-tts/codes/data/audio/paired_voice_audio_dataset.py\", line 194, in __getitem__\n",
            "    tseq, wav, text, path, type = self.get_wav_text_pair(self.audiopaths_and_text[index])\n",
            "  File \"/content/ibibio-tts/codes/data/audio/paired_voice_audio_dataset.py\", line 177, in get_wav_text_pair\n",
            "    text_seq = self.get_text(text)\n",
            "  File \"/content/ibibio-tts/codes/data/audio/paired_voice_audio_dataset.py\", line 186, in get_text\n",
            "    assert not torch.any(tokens == 1)\n",
            "AssertionError\n",
            "\n",
            "During handling of the above exception, another exception occurred:\n",
            "\n",
            "Traceback (most recent call last):\n",
            "  File \"/content/ibibio-tts/codes/data/audio/paired_voice_audio_dataset.py\", line 194, in __getitem__\n",
            "    tseq, wav, text, path, type = self.get_wav_text_pair(self.audiopaths_and_text[index])\n",
            "  File \"/content/ibibio-tts/codes/data/audio/paired_voice_audio_dataset.py\", line 178, in get_wav_text_pair\n",
            "    wav = load_audio(audiopath, self.sample_rate)\n",
            "  File \"/content/ibibio-tts/codes/data/audio/unsupervised_audio_dataset.py\", line 19, in load_audio\n",
            "    audio, lsr = load_wav_to_torch(audiopath)\n",
            "  File \"/content/ibibio-tts/codes/models/audio/tts/tacotron2/taco_utils.py\", line 17, in load_wav_to_torch\n",
            "    sampling_rate, data = read(full_path)\n",
            "  File \"/usr/local/lib/python3.10/dist-packages/scipy/io/wavfile.py\", line 647, in read\n",
            "    fid = open(filename, 'rb')\n",
            "FileNotFoundError: [Errno 2] No such file or directory: '/content/drive/MyDrive/dataset/wav_split/wavs//content/drive/MyDrive/dataset/wav/209.wav'\n",
            "\n",
            "During handling of the above exception, another exception occurred:\n",
            "\n",
            "Traceback (most recent call last):\n",
            "  File \"/content/ibibio-tts/codes/data/audio/paired_voice_audio_dataset.py\", line 194, in __getitem__\n",
            "    tseq, wav, text, path, type = self.get_wav_text_pair(self.audiopaths_and_text[index])\n",
            "  File \"/content/ibibio-tts/codes/data/audio/paired_voice_audio_dataset.py\", line 178, in get_wav_text_pair\n",
            "    wav = load_audio(audiopath, self.sample_rate)\n",
            "  File \"/content/ibibio-tts/codes/data/audio/unsupervised_audio_dataset.py\", line 19, in load_audio\n",
            "    audio, lsr = load_wav_to_torch(audiopath)\n",
            "  File \"/content/ibibio-tts/codes/models/audio/tts/tacotron2/taco_utils.py\", line 17, in load_wav_to_torch\n",
            "    sampling_rate, data = read(full_path)\n",
            "  File \"/usr/local/lib/python3.10/dist-packages/scipy/io/wavfile.py\", line 647, in read\n",
            "    fid = open(filename, 'rb')\n",
            "FileNotFoundError: [Errno 2] No such file or directory: '/content/drive/MyDrive/dataset/wav_split/wavs//content/drive/MyDrive/dataset/wav/624.wav'\n",
            "\n",
            "During handling of the above exception, another exception occurred:\n",
            "\n",
            "Traceback (most recent call last):\n",
            "  File \"/content/ibibio-tts/codes/data/audio/paired_voice_audio_dataset.py\", line 194, in __getitem__\n",
            "    tseq, wav, text, path, type = self.get_wav_text_pair(self.audiopaths_and_text[index])\n",
            "  File \"/content/ibibio-tts/codes/data/audio/paired_voice_audio_dataset.py\", line 178, in get_wav_text_pair\n",
            "    wav = load_audio(audiopath, self.sample_rate)\n",
            "  File \"/content/ibibio-tts/codes/data/audio/unsupervised_audio_dataset.py\", line 19, in load_audio\n",
            "    audio, lsr = load_wav_to_torch(audiopath)\n",
            "  File \"/content/ibibio-tts/codes/models/audio/tts/tacotron2/taco_utils.py\", line 17, in load_wav_to_torch\n",
            "    sampling_rate, data = read(full_path)\n",
            "  File \"/usr/local/lib/python3.10/dist-packages/scipy/io/wavfile.py\", line 647, in read\n",
            "    fid = open(filename, 'rb')\n",
            "FileNotFoundError: [Errno 2] No such file or directory: '/content/drive/MyDrive/dataset/wav_split/wavs//content/drive/MyDrive/dataset/wav/316.wav'\n",
            "\n",
            "During handling of the above exception, another exception occurred:\n",
            "\n",
            "Traceback (most recent call last):\n",
            "  File \"/content/ibibio-tts/codes/data/audio/paired_voice_audio_dataset.py\", line 194, in __getitem__\n",
            "    tseq, wav, text, path, type = self.get_wav_text_pair(self.audiopaths_and_text[index])\n",
            "  File \"/content/ibibio-tts/codes/data/audio/paired_voice_audio_dataset.py\", line 178, in get_wav_text_pair\n",
            "    wav = load_audio(audiopath, self.sample_rate)\n",
            "  File \"/content/ibibio-tts/codes/data/audio/unsupervised_audio_dataset.py\", line 19, in load_audio\n",
            "    audio, lsr = load_wav_to_torch(audiopath)\n",
            "  File \"/content/ibibio-tts/codes/models/audio/tts/tacotron2/taco_utils.py\", line 17, in load_wav_to_torch\n",
            "    sampling_rate, data = read(full_path)\n",
            "  File \"/usr/local/lib/python3.10/dist-packages/scipy/io/wavfile.py\", line 647, in read\n",
            "    fid = open(filename, 'rb')\n",
            "FileNotFoundError: [Errno 2] No such file or directory: '/content/drive/MyDrive/dataset/wav_split/wavs//content/drive/MyDrive/dataset/wav/599.wav'\n",
            "\n",
            "During handling of the above exception, another exception occurred:\n",
            "\n",
            "Traceback (most recent call last):\n",
            "  File \"/content/ibibio-tts/codes/data/audio/paired_voice_audio_dataset.py\", line 194, in __getitem__\n",
            "    tseq, wav, text, path, type = self.get_wav_text_pair(self.audiopaths_and_text[index])\n",
            "  File \"/content/ibibio-tts/codes/data/audio/paired_voice_audio_dataset.py\", line 178, in get_wav_text_pair\n",
            "    wav = load_audio(audiopath, self.sample_rate)\n",
            "  File \"/content/ibibio-tts/codes/data/audio/unsupervised_audio_dataset.py\", line 19, in load_audio\n",
            "    audio, lsr = load_wav_to_torch(audiopath)\n",
            "  File \"/content/ibibio-tts/codes/models/audio/tts/tacotron2/taco_utils.py\", line 17, in load_wav_to_torch\n",
            "    sampling_rate, data = read(full_path)\n",
            "  File \"/usr/local/lib/python3.10/dist-packages/scipy/io/wavfile.py\", line 647, in read\n",
            "    fid = open(filename, 'rb')\n",
            "FileNotFoundError: [Errno 2] No such file or directory: '/content/drive/MyDrive/dataset/wav_split/wavs//content/drive/MyDrive/dataset/wav/475.wav'\n",
            "\n",
            "During handling of the above exception, another exception occurred:\n",
            "\n",
            "Traceback (most recent call last):\n",
            "  File \"/content/ibibio-tts/codes/data/audio/paired_voice_audio_dataset.py\", line 194, in __getitem__\n",
            "    tseq, wav, text, path, type = self.get_wav_text_pair(self.audiopaths_and_text[index])\n",
            "  File \"/content/ibibio-tts/codes/data/audio/paired_voice_audio_dataset.py\", line 178, in get_wav_text_pair\n",
            "    wav = load_audio(audiopath, self.sample_rate)\n",
            "  File \"/content/ibibio-tts/codes/data/audio/unsupervised_audio_dataset.py\", line 19, in load_audio\n",
            "    audio, lsr = load_wav_to_torch(audiopath)\n",
            "  File \"/content/ibibio-tts/codes/models/audio/tts/tacotron2/taco_utils.py\", line 17, in load_wav_to_torch\n",
            "    sampling_rate, data = read(full_path)\n",
            "  File \"/usr/local/lib/python3.10/dist-packages/scipy/io/wavfile.py\", line 647, in read\n",
            "    fid = open(filename, 'rb')\n",
            "FileNotFoundError: [Errno 2] No such file or directory: '/content/drive/MyDrive/dataset/wav_split/wavs//content/drive/MyDrive/dataset/wav/227.wav'\n",
            "\n",
            "During handling of the above exception, another exception occurred:\n",
            "\n",
            "Traceback (most recent call last):\n",
            "  File \"/content/ibibio-tts/codes/data/audio/paired_voice_audio_dataset.py\", line 194, in __getitem__\n",
            "    tseq, wav, text, path, type = self.get_wav_text_pair(self.audiopaths_and_text[index])\n",
            "  File \"/content/ibibio-tts/codes/data/audio/paired_voice_audio_dataset.py\", line 178, in get_wav_text_pair\n",
            "    wav = load_audio(audiopath, self.sample_rate)\n",
            "  File \"/content/ibibio-tts/codes/data/audio/unsupervised_audio_dataset.py\", line 19, in load_audio\n",
            "    audio, lsr = load_wav_to_torch(audiopath)\n",
            "  File \"/content/ibibio-tts/codes/models/audio/tts/tacotron2/taco_utils.py\", line 17, in load_wav_to_torch\n",
            "    sampling_rate, data = read(full_path)\n",
            "  File \"/usr/local/lib/python3.10/dist-packages/scipy/io/wavfile.py\", line 647, in read\n",
            "    fid = open(filename, 'rb')\n",
            "FileNotFoundError: [Errno 2] No such file or directory: '/content/drive/MyDrive/dataset/wav_split/wavs//content/drive/MyDrive/dataset/wav/465.wav'\n",
            "\n",
            "During handling of the above exception, another exception occurred:\n",
            "\n",
            "Traceback (most recent call last):\n",
            "  File \"/content/ibibio-tts/codes/data/audio/paired_voice_audio_dataset.py\", line 194, in __getitem__\n",
            "    tseq, wav, text, path, type = self.get_wav_text_pair(self.audiopaths_and_text[index])\n",
            "  File \"/content/ibibio-tts/codes/data/audio/paired_voice_audio_dataset.py\", line 178, in get_wav_text_pair\n",
            "    wav = load_audio(audiopath, self.sample_rate)\n",
            "  File \"/content/ibibio-tts/codes/data/audio/unsupervised_audio_dataset.py\", line 19, in load_audio\n",
            "    audio, lsr = load_wav_to_torch(audiopath)\n",
            "  File \"/content/ibibio-tts/codes/models/audio/tts/tacotron2/taco_utils.py\", line 17, in load_wav_to_torch\n",
            "    sampling_rate, data = read(full_path)\n",
            "  File \"/usr/local/lib/python3.10/dist-packages/scipy/io/wavfile.py\", line 647, in read\n",
            "    fid = open(filename, 'rb')\n",
            "FileNotFoundError: [Errno 2] No such file or directory: '/content/drive/MyDrive/dataset/wav_split/wavs//content/drive/MyDrive/dataset/wav/234.wav'\n",
            "\n",
            "During handling of the above exception, another exception occurred:\n",
            "\n",
            "Traceback (most recent call last):\n",
            "  File \"/content/ibibio-tts/codes/data/audio/paired_voice_audio_dataset.py\", line 194, in __getitem__\n",
            "    tseq, wav, text, path, type = self.get_wav_text_pair(self.audiopaths_and_text[index])\n",
            "  File \"/content/ibibio-tts/codes/data/audio/paired_voice_audio_dataset.py\", line 178, in get_wav_text_pair\n",
            "    wav = load_audio(audiopath, self.sample_rate)\n",
            "  File \"/content/ibibio-tts/codes/data/audio/unsupervised_audio_dataset.py\", line 19, in load_audio\n",
            "    audio, lsr = load_wav_to_torch(audiopath)\n",
            "  File \"/content/ibibio-tts/codes/models/audio/tts/tacotron2/taco_utils.py\", line 17, in load_wav_to_torch\n",
            "    sampling_rate, data = read(full_path)\n",
            "  File \"/usr/local/lib/python3.10/dist-packages/scipy/io/wavfile.py\", line 647, in read\n",
            "    fid = open(filename, 'rb')\n",
            "FileNotFoundError: [Errno 2] No such file or directory: '/content/drive/MyDrive/dataset/wav_split/wavs//content/drive/MyDrive/dataset/wav/601.wav'\n",
            "\n",
            "During handling of the above exception, another exception occurred:\n",
            "\n",
            "Traceback (most recent call last):\n",
            "  File \"/content/ibibio-tts/codes/data/audio/paired_voice_audio_dataset.py\", line 194, in __getitem__\n",
            "    tseq, wav, text, path, type = self.get_wav_text_pair(self.audiopaths_and_text[index])\n",
            "  File \"/content/ibibio-tts/codes/data/audio/paired_voice_audio_dataset.py\", line 178, in get_wav_text_pair\n",
            "    wav = load_audio(audiopath, self.sample_rate)\n",
            "  File \"/content/ibibio-tts/codes/data/audio/unsupervised_audio_dataset.py\", line 19, in load_audio\n",
            "    audio, lsr = load_wav_to_torch(audiopath)\n",
            "  File \"/content/ibibio-tts/codes/models/audio/tts/tacotron2/taco_utils.py\", line 17, in load_wav_to_torch\n",
            "    sampling_rate, data = read(full_path)\n",
            "  File \"/usr/local/lib/python3.10/dist-packages/scipy/io/wavfile.py\", line 647, in read\n",
            "    fid = open(filename, 'rb')\n",
            "FileNotFoundError: [Errno 2] No such file or directory: '/content/drive/MyDrive/dataset/wav_split/wavs//content/drive/MyDrive/dataset/wav/408.wav'\n",
            "\n",
            "During handling of the above exception, another exception occurred:\n",
            "\n",
            "Traceback (most recent call last):\n",
            "  File \"/content/ibibio-tts/codes/data/audio/paired_voice_audio_dataset.py\", line 194, in __getitem__\n",
            "    tseq, wav, text, path, type = self.get_wav_text_pair(self.audiopaths_and_text[index])\n",
            "  File \"/content/ibibio-tts/codes/data/audio/paired_voice_audio_dataset.py\", line 177, in get_wav_text_pair\n",
            "    text_seq = self.get_text(text)\n",
            "  File \"/content/ibibio-tts/codes/data/audio/paired_voice_audio_dataset.py\", line 186, in get_text\n",
            "    assert not torch.any(tokens == 1)\n",
            "AssertionError\n",
            "\n",
            "During handling of the above exception, another exception occurred:\n",
            "\n",
            "Traceback (most recent call last):\n",
            "  File \"/content/ibibio-tts/codes/data/audio/paired_voice_audio_dataset.py\", line 194, in __getitem__\n",
            "    tseq, wav, text, path, type = self.get_wav_text_pair(self.audiopaths_and_text[index])\n",
            "  File \"/content/ibibio-tts/codes/data/audio/paired_voice_audio_dataset.py\", line 178, in get_wav_text_pair\n",
            "    wav = load_audio(audiopath, self.sample_rate)\n",
            "  File \"/content/ibibio-tts/codes/data/audio/unsupervised_audio_dataset.py\", line 19, in load_audio\n",
            "    audio, lsr = load_wav_to_torch(audiopath)\n",
            "  File \"/content/ibibio-tts/codes/models/audio/tts/tacotron2/taco_utils.py\", line 17, in load_wav_to_torch\n",
            "    sampling_rate, data = read(full_path)\n",
            "  File \"/usr/local/lib/python3.10/dist-packages/scipy/io/wavfile.py\", line 647, in read\n",
            "    fid = open(filename, 'rb')\n",
            "FileNotFoundError: [Errno 2] No such file or directory: '/content/drive/MyDrive/dataset/wav_split/wavs//content/drive/MyDrive/dataset/wav/573.wav'\n",
            "\n",
            "During handling of the above exception, another exception occurred:\n",
            "\n",
            "Traceback (most recent call last):\n",
            "  File \"/content/ibibio-tts/codes/data/audio/paired_voice_audio_dataset.py\", line 194, in __getitem__\n",
            "    tseq, wav, text, path, type = self.get_wav_text_pair(self.audiopaths_and_text[index])\n",
            "  File \"/content/ibibio-tts/codes/data/audio/paired_voice_audio_dataset.py\", line 178, in get_wav_text_pair\n",
            "    wav = load_audio(audiopath, self.sample_rate)\n",
            "  File \"/content/ibibio-tts/codes/data/audio/unsupervised_audio_dataset.py\", line 19, in load_audio\n",
            "    audio, lsr = load_wav_to_torch(audiopath)\n",
            "  File \"/content/ibibio-tts/codes/models/audio/tts/tacotron2/taco_utils.py\", line 17, in load_wav_to_torch\n",
            "    sampling_rate, data = read(full_path)\n",
            "  File \"/usr/local/lib/python3.10/dist-packages/scipy/io/wavfile.py\", line 647, in read\n",
            "    fid = open(filename, 'rb')\n",
            "FileNotFoundError: [Errno 2] No such file or directory: '/content/drive/MyDrive/dataset/wav_split/wavs//content/drive/MyDrive/dataset/wav/246.wav'\n",
            "\n",
            "During handling of the above exception, another exception occurred:\n",
            "\n",
            "Traceback (most recent call last):\n",
            "  File \"/content/ibibio-tts/codes/data/audio/paired_voice_audio_dataset.py\", line 194, in __getitem__\n",
            "    tseq, wav, text, path, type = self.get_wav_text_pair(self.audiopaths_and_text[index])\n",
            "  File \"/content/ibibio-tts/codes/data/audio/paired_voice_audio_dataset.py\", line 178, in get_wav_text_pair\n",
            "    wav = load_audio(audiopath, self.sample_rate)\n",
            "  File \"/content/ibibio-tts/codes/data/audio/unsupervised_audio_dataset.py\", line 19, in load_audio\n",
            "    audio, lsr = load_wav_to_torch(audiopath)\n",
            "  File \"/content/ibibio-tts/codes/models/audio/tts/tacotron2/taco_utils.py\", line 17, in load_wav_to_torch\n",
            "    sampling_rate, data = read(full_path)\n",
            "  File \"/usr/local/lib/python3.10/dist-packages/scipy/io/wavfile.py\", line 647, in read\n",
            "    fid = open(filename, 'rb')\n",
            "FileNotFoundError: [Errno 2] No such file or directory: '/content/drive/MyDrive/dataset/wav_split/wavs//content/drive/MyDrive/dataset/wav/150.wav'\n",
            "\n",
            "During handling of the above exception, another exception occurred:\n",
            "\n",
            "Traceback (most recent call last):\n",
            "  File \"/content/ibibio-tts/codes/data/audio/paired_voice_audio_dataset.py\", line 194, in __getitem__\n",
            "    tseq, wav, text, path, type = self.get_wav_text_pair(self.audiopaths_and_text[index])\n",
            "  File \"/content/ibibio-tts/codes/data/audio/paired_voice_audio_dataset.py\", line 178, in get_wav_text_pair\n",
            "    wav = load_audio(audiopath, self.sample_rate)\n",
            "  File \"/content/ibibio-tts/codes/data/audio/unsupervised_audio_dataset.py\", line 19, in load_audio\n",
            "    audio, lsr = load_wav_to_torch(audiopath)\n",
            "  File \"/content/ibibio-tts/codes/models/audio/tts/tacotron2/taco_utils.py\", line 17, in load_wav_to_torch\n",
            "    sampling_rate, data = read(full_path)\n",
            "  File \"/usr/local/lib/python3.10/dist-packages/scipy/io/wavfile.py\", line 647, in read\n",
            "    fid = open(filename, 'rb')\n",
            "FileNotFoundError: [Errno 2] No such file or directory: '/content/drive/MyDrive/dataset/wav_split/wavs//content/drive/MyDrive/dataset/wav/435.wav'\n",
            "\n",
            "During handling of the above exception, another exception occurred:\n",
            "\n",
            "Traceback (most recent call last):\n",
            "  File \"/content/ibibio-tts/codes/data/audio/paired_voice_audio_dataset.py\", line 194, in __getitem__\n",
            "    tseq, wav, text, path, type = self.get_wav_text_pair(self.audiopaths_and_text[index])\n",
            "  File \"/content/ibibio-tts/codes/data/audio/paired_voice_audio_dataset.py\", line 178, in get_wav_text_pair\n",
            "    wav = load_audio(audiopath, self.sample_rate)\n",
            "  File \"/content/ibibio-tts/codes/data/audio/unsupervised_audio_dataset.py\", line 19, in load_audio\n",
            "    audio, lsr = load_wav_to_torch(audiopath)\n",
            "  File \"/content/ibibio-tts/codes/models/audio/tts/tacotron2/taco_utils.py\", line 17, in load_wav_to_torch\n",
            "    sampling_rate, data = read(full_path)\n",
            "  File \"/usr/local/lib/python3.10/dist-packages/scipy/io/wavfile.py\", line 647, in read\n",
            "    fid = open(filename, 'rb')\n",
            "FileNotFoundError: [Errno 2] No such file or directory: '/content/drive/MyDrive/dataset/wav_split/wavs//content/drive/MyDrive/dataset/wav/642.wav'\n",
            "\n",
            "During handling of the above exception, another exception occurred:\n",
            "\n",
            "Traceback (most recent call last):\n",
            "  File \"/content/ibibio-tts/codes/data/audio/paired_voice_audio_dataset.py\", line 194, in __getitem__\n",
            "    tseq, wav, text, path, type = self.get_wav_text_pair(self.audiopaths_and_text[index])\n",
            "  File \"/content/ibibio-tts/codes/data/audio/paired_voice_audio_dataset.py\", line 178, in get_wav_text_pair\n",
            "    wav = load_audio(audiopath, self.sample_rate)\n",
            "  File \"/content/ibibio-tts/codes/data/audio/unsupervised_audio_dataset.py\", line 19, in load_audio\n",
            "    audio, lsr = load_wav_to_torch(audiopath)\n",
            "  File \"/content/ibibio-tts/codes/models/audio/tts/tacotron2/taco_utils.py\", line 17, in load_wav_to_torch\n",
            "    sampling_rate, data = read(full_path)\n",
            "  File \"/usr/local/lib/python3.10/dist-packages/scipy/io/wavfile.py\", line 647, in read\n",
            "    fid = open(filename, 'rb')\n",
            "FileNotFoundError: [Errno 2] No such file or directory: '/content/drive/MyDrive/dataset/wav_split/wavs//content/drive/MyDrive/dataset/wav/495.wav'\n",
            "\n",
            "During handling of the above exception, another exception occurred:\n",
            "\n",
            "Traceback (most recent call last):\n",
            "  File \"/content/ibibio-tts/codes/data/audio/paired_voice_audio_dataset.py\", line 194, in __getitem__\n",
            "    tseq, wav, text, path, type = self.get_wav_text_pair(self.audiopaths_and_text[index])\n",
            "  File \"/content/ibibio-tts/codes/data/audio/paired_voice_audio_dataset.py\", line 178, in get_wav_text_pair\n",
            "    wav = load_audio(audiopath, self.sample_rate)\n",
            "  File \"/content/ibibio-tts/codes/data/audio/unsupervised_audio_dataset.py\", line 19, in load_audio\n",
            "    audio, lsr = load_wav_to_torch(audiopath)\n",
            "  File \"/content/ibibio-tts/codes/models/audio/tts/tacotron2/taco_utils.py\", line 17, in load_wav_to_torch\n",
            "    sampling_rate, data = read(full_path)\n",
            "  File \"/usr/local/lib/python3.10/dist-packages/scipy/io/wavfile.py\", line 647, in read\n",
            "    fid = open(filename, 'rb')\n",
            "FileNotFoundError: [Errno 2] No such file or directory: '/content/drive/MyDrive/dataset/wav_split/wavs//content/drive/MyDrive/dataset/wav/40.wav'\n",
            "\n",
            "During handling of the above exception, another exception occurred:\n",
            "\n",
            "Traceback (most recent call last):\n",
            "  File \"/content/ibibio-tts/codes/data/audio/paired_voice_audio_dataset.py\", line 194, in __getitem__\n",
            "    tseq, wav, text, path, type = self.get_wav_text_pair(self.audiopaths_and_text[index])\n",
            "  File \"/content/ibibio-tts/codes/data/audio/paired_voice_audio_dataset.py\", line 178, in get_wav_text_pair\n",
            "    wav = load_audio(audiopath, self.sample_rate)\n",
            "  File \"/content/ibibio-tts/codes/data/audio/unsupervised_audio_dataset.py\", line 19, in load_audio\n",
            "    audio, lsr = load_wav_to_torch(audiopath)\n",
            "  File \"/content/ibibio-tts/codes/models/audio/tts/tacotron2/taco_utils.py\", line 17, in load_wav_to_torch\n",
            "    sampling_rate, data = read(full_path)\n",
            "  File \"/usr/local/lib/python3.10/dist-packages/scipy/io/wavfile.py\", line 647, in read\n",
            "    fid = open(filename, 'rb')\n",
            "FileNotFoundError: [Errno 2] No such file or directory: '/content/drive/MyDrive/dataset/wav_split/wavs//content/drive/MyDrive/dataset/wav/322.wav'\n",
            "\n",
            "During handling of the above exception, another exception occurred:\n",
            "\n",
            "Traceback (most recent call last):\n",
            "  File \"/content/ibibio-tts/codes/data/audio/paired_voice_audio_dataset.py\", line 194, in __getitem__\n",
            "    tseq, wav, text, path, type = self.get_wav_text_pair(self.audiopaths_and_text[index])\n",
            "  File \"/content/ibibio-tts/codes/data/audio/paired_voice_audio_dataset.py\", line 178, in get_wav_text_pair\n",
            "    wav = load_audio(audiopath, self.sample_rate)\n",
            "  File \"/content/ibibio-tts/codes/data/audio/unsupervised_audio_dataset.py\", line 19, in load_audio\n",
            "    audio, lsr = load_wav_to_torch(audiopath)\n",
            "  File \"/content/ibibio-tts/codes/models/audio/tts/tacotron2/taco_utils.py\", line 17, in load_wav_to_torch\n",
            "    sampling_rate, data = read(full_path)\n",
            "  File \"/usr/local/lib/python3.10/dist-packages/scipy/io/wavfile.py\", line 647, in read\n",
            "    fid = open(filename, 'rb')\n",
            "FileNotFoundError: [Errno 2] No such file or directory: '/content/drive/MyDrive/dataset/wav_split/wavs//content/drive/MyDrive/dataset/wav/398.wav'\n",
            "\n",
            "During handling of the above exception, another exception occurred:\n",
            "\n",
            "Traceback (most recent call last):\n",
            "  File \"/content/ibibio-tts/codes/data/audio/paired_voice_audio_dataset.py\", line 194, in __getitem__\n",
            "    tseq, wav, text, path, type = self.get_wav_text_pair(self.audiopaths_and_text[index])\n",
            "  File \"/content/ibibio-tts/codes/data/audio/paired_voice_audio_dataset.py\", line 178, in get_wav_text_pair\n",
            "    wav = load_audio(audiopath, self.sample_rate)\n",
            "  File \"/content/ibibio-tts/codes/data/audio/unsupervised_audio_dataset.py\", line 19, in load_audio\n",
            "    audio, lsr = load_wav_to_torch(audiopath)\n",
            "  File \"/content/ibibio-tts/codes/models/audio/tts/tacotron2/taco_utils.py\", line 17, in load_wav_to_torch\n",
            "    sampling_rate, data = read(full_path)\n",
            "  File \"/usr/local/lib/python3.10/dist-packages/scipy/io/wavfile.py\", line 647, in read\n",
            "    fid = open(filename, 'rb')\n",
            "FileNotFoundError: [Errno 2] No such file or directory: '/content/drive/MyDrive/dataset/wav_split/wavs//content/drive/MyDrive/dataset/wav/460.wav'\n",
            "\n",
            "During handling of the above exception, another exception occurred:\n",
            "\n",
            "Traceback (most recent call last):\n",
            "  File \"/usr/local/lib/python3.10/dist-packages/torch/utils/data/_utils/worker.py\", line 308, in _worker_loop\n",
            "    data = fetcher.fetch(index)  # type: ignore[possibly-undefined]\n",
            "  File \"/usr/local/lib/python3.10/dist-packages/torch/utils/data/_utils/fetch.py\", line 51, in fetch\n",
            "    data = [self.dataset[idx] for idx in possibly_batched_index]\n",
            "  File \"/usr/local/lib/python3.10/dist-packages/torch/utils/data/_utils/fetch.py\", line 51, in <listcomp>\n",
            "    data = [self.dataset[idx] for idx in possibly_batched_index]\n",
            "  File \"/content/ibibio-tts/codes/data/audio/paired_voice_audio_dataset.py\", line 207, in __getitem__\n",
            "    return self[(index+1) % len(self)]\n",
            "  File \"/content/ibibio-tts/codes/data/audio/paired_voice_audio_dataset.py\", line 207, in __getitem__\n",
            "    return self[(index+1) % len(self)]\n",
            "  File \"/content/ibibio-tts/codes/data/audio/paired_voice_audio_dataset.py\", line 207, in __getitem__\n",
            "    return self[(index+1) % len(self)]\n",
            "  [Previous line repeated 97 more times]\n",
            "  File \"/content/ibibio-tts/codes/data/audio/paired_voice_audio_dataset.py\", line 194, in __getitem__\n",
            "    tseq, wav, text, path, type = self.get_wav_text_pair(self.audiopaths_and_text[index])\n",
            "  File \"/content/ibibio-tts/codes/data/audio/paired_voice_audio_dataset.py\", line 178, in get_wav_text_pair\n",
            "    wav = load_audio(audiopath, self.sample_rate)\n",
            "  File \"/content/ibibio-tts/codes/data/audio/unsupervised_audio_dataset.py\", line 19, in load_audio\n",
            "    audio, lsr = load_wav_to_torch(audiopath)\n",
            "  File \"/content/ibibio-tts/codes/models/audio/tts/tacotron2/taco_utils.py\", line 17, in load_wav_to_torch\n",
            "    sampling_rate, data = read(full_path)\n",
            "  File \"/usr/local/lib/python3.10/dist-packages/scipy/io/wavfile.py\", line 647, in read\n",
            "    fid = open(filename, 'rb')\n",
            "FileNotFoundError: [Errno 2] No such file or directory: '/content/drive/MyDrive/dataset/wav_split/wavs//content/drive/MyDrive/dataset/wav/513.wav'\n",
            "\n"
          ]
        }
      ]
    },
    {
      "cell_type": "code",
      "source": [
        "!pip install transformers==4.33.2"
      ],
      "metadata": {
        "id": "GdS6XIiqcdLx",
        "outputId": "8db7dd3e-eea3-4b74-e3a3-5a7b7b662b5f",
        "colab": {
          "base_uri": "https://localhost:8080/"
        }
      },
      "execution_count": 2,
      "outputs": [
        {
          "output_type": "stream",
          "name": "stdout",
          "text": [
            "Requirement already satisfied: transformers==4.33.2 in /usr/local/lib/python3.10/dist-packages (4.33.2)\n",
            "Requirement already satisfied: filelock in /usr/local/lib/python3.10/dist-packages (from transformers==4.33.2) (3.14.0)\n",
            "Requirement already satisfied: huggingface-hub<1.0,>=0.15.1 in /usr/local/lib/python3.10/dist-packages (from transformers==4.33.2) (0.23.1)\n",
            "Requirement already satisfied: numpy>=1.17 in /usr/local/lib/python3.10/dist-packages (from transformers==4.33.2) (1.25.2)\n",
            "Requirement already satisfied: packaging>=20.0 in /usr/local/lib/python3.10/dist-packages (from transformers==4.33.2) (24.0)\n",
            "Requirement already satisfied: pyyaml>=5.1 in /usr/local/lib/python3.10/dist-packages (from transformers==4.33.2) (6.0.1)\n",
            "Requirement already satisfied: regex!=2019.12.17 in /usr/local/lib/python3.10/dist-packages (from transformers==4.33.2) (2024.5.15)\n",
            "Requirement already satisfied: requests in /usr/local/lib/python3.10/dist-packages (from transformers==4.33.2) (2.31.0)\n",
            "Requirement already satisfied: tokenizers!=0.11.3,<0.14,>=0.11.1 in /usr/local/lib/python3.10/dist-packages (from transformers==4.33.2) (0.13.3)\n",
            "Requirement already satisfied: safetensors>=0.3.1 in /usr/local/lib/python3.10/dist-packages (from transformers==4.33.2) (0.4.3)\n",
            "Requirement already satisfied: tqdm>=4.27 in /usr/local/lib/python3.10/dist-packages (from transformers==4.33.2) (4.66.4)\n",
            "Requirement already satisfied: fsspec>=2023.5.0 in /usr/local/lib/python3.10/dist-packages (from huggingface-hub<1.0,>=0.15.1->transformers==4.33.2) (2023.6.0)\n",
            "Requirement already satisfied: typing-extensions>=3.7.4.3 in /usr/local/lib/python3.10/dist-packages (from huggingface-hub<1.0,>=0.15.1->transformers==4.33.2) (4.11.0)\n",
            "Requirement already satisfied: charset-normalizer<4,>=2 in /usr/local/lib/python3.10/dist-packages (from requests->transformers==4.33.2) (3.3.2)\n",
            "Requirement already satisfied: idna<4,>=2.5 in /usr/local/lib/python3.10/dist-packages (from requests->transformers==4.33.2) (3.7)\n",
            "Requirement already satisfied: urllib3<3,>=1.21.1 in /usr/local/lib/python3.10/dist-packages (from requests->transformers==4.33.2) (2.0.7)\n",
            "Requirement already satisfied: certifi>=2017.4.17 in /usr/local/lib/python3.10/dist-packages (from requests->transformers==4.33.2) (2024.2.2)\n"
          ]
        }
      ]
    },
    {
      "cell_type": "code",
      "source": [
        "import os\n",
        "print(os.getcwd())\n"
      ],
      "metadata": {
        "colab": {
          "base_uri": "https://localhost:8080/"
        },
        "id": "mEmI8DPrTiNb",
        "outputId": "e821a4ea-f886-48bb-f1b1-6836dd7ba276"
      },
      "execution_count": 20,
      "outputs": [
        {
          "output_type": "stream",
          "name": "stdout",
          "text": [
            "/content/ibibio-tts/codes\n"
          ]
        }
      ]
    },
    {
      "cell_type": "code",
      "source": [
        "import tokenizers\n",
        "print(tokenizers.__version__)\n"
      ],
      "metadata": {
        "id": "SjPOt6ZGUKXN",
        "colab": {
          "base_uri": "https://localhost:8080/"
        },
        "outputId": "bcd256e7-4849-48fa-9c69-ad034fa4d63a"
      },
      "execution_count": 13,
      "outputs": [
        {
          "output_type": "stream",
          "name": "stdout",
          "text": [
            "0.13.3\n"
          ]
        }
      ]
    },
    {
      "cell_type": "code",
      "source": [
        "import re\n",
        "import torch\n",
        "from tokenizers import Tokenizer\n",
        "from tokenizers.models import BPE\n",
        "from tokenizers.pre_tokenizers import Whitespace\n",
        "from tokenizers.trainers import BpeTrainer\n",
        "\n",
        "\n",
        "\n",
        "def remove_extraneous_punctuation(word):\n",
        "    replacement_punctuation = {\n",
        "        '{': '(', '}': ')',\n",
        "        '[': '(', ']': ')',\n",
        "        '`': '\\'', '—': '-',\n",
        "        '—': '-', '`': '\\'',\n",
        "        'ʼ': '\\''\n",
        "    }\n",
        "    replace = re.compile(\"|\".join([re.escape(k) for k in sorted(replacement_punctuation, key=len, reverse=True)]), flags=re.DOTALL)\n",
        "    word = replace.sub(lambda x: replacement_punctuation[x.group(0)], word)\n",
        "    extraneous = re.compile(r'^[@#%_=\\$\\^&\\*\\+\\\\]$')\n",
        "    word = extraneous.sub('', word)\n",
        "    return word\n",
        "\n",
        "with open('transcriptions.txt', 'r', encoding='utf-8') as at:\n",
        "    ttsd = at.readlines()\n",
        "    allowed_characters_re = re.compile(r'^[a-zịñọʌ!:;\"/, \\-\\(\\)\\.\\'\\?ʼ]+$')\n",
        "\n",
        "    def preprocess_word(word, report=False):\n",
        "        word = remove_extraneous_punctuation(word)\n",
        "        if not bool(allowed_characters_re.match(word)):\n",
        "            if report and word:\n",
        "                print(f\"REPORTING: '{word}'\")\n",
        "            return ''\n",
        "        return word\n",
        "\n",
        "    def batch_iterator(batch_size=1000):\n",
        "        print(\"Processing ASR texts.\")\n",
        "        for i in range(0, len(ttsd), batch_size):\n",
        "            yield [preprocess_word(t, True) for t in ttsd[i:i+batch_size]]\n",
        "\n",
        "    trainer = BpeTrainer(special_tokens=['[STOP]', '[UNK]', '[SPACE]'], vocab_size=255)\n",
        "    tokenizer = Tokenizer(BPE(unk_token=\"[UNK]\"))\n",
        "    tokenizer.pre_tokenizer = Whitespace()\n",
        "    tokenizer.train_from_iterator(batch_iterator(), trainer, length=len(ttsd))\n",
        "    tokenizer.save('./custom_language_tokenizer.json')\n",
        "\n",
        "    # Save the tokenizer to hub\n",
        "    tokenizer.push_to_hub(repo_id='aidystark/ibibio-tokenizer')"
      ],
      "metadata": {
        "id": "QIXVBNHEav3C"
      },
      "execution_count": null,
      "outputs": []
    },
    {
      "cell_type": "code",
      "source": [],
      "metadata": {
        "id": "YZF5QuOAf5Bp"
      },
      "execution_count": null,
      "outputs": []
    }
  ]
}